<?xml version="1.0" encoding="utf-8"?>
<!-- =================================================================================== -->
<!-- |    This document was autogenerated by xacro from /home/ubuntu/catkin_ws/src/origarm_ros/model/urdf/origarmRigidKE.urdf.xacro | -->
<!-- |    EDITING THIS FILE BY HAND IS NOT RECOMMENDED                                 | -->
<!-- =================================================================================== -->
<robot name="origarmRigidKE">
  <material name="black">
    <color rgba="0.0 0.0 0.0 1.0"/>
  </material>
  <material name="blue">
    <color rgba="0.0 0.0 0.8 1.0"/>
  </material>
  <material name="green">
    <color rgba="0.0 0.8 0.0 1.0"/>
  </material>
  <material name="grey">
    <color rgba="0.2 0.2 0.2 1.0"/>
  </material>
  <material name="orange">
    <color rgba="1.0 0.423529411765 0.0392156862745 1.0"/>
  </material>
  <material name="brown">
    <color rgba="0.870588235294 0.811764705882 0.764705882353 1.0"/>
  </material>
  <material name="red">
    <color rgba="0.8 0.0 0.0 1.0"/>
  </material>
  <material name="white">
    <color rgba="1.0 1.0 1.0 1.0"/>
  </material>
  <material name="aluminum">
    <color rgba="0.517647058824 0.529411764706 0.537254901961 1.0"/>
  </material>
  <link name="world"/>
  <joint name="fixed" type="fixed">
    <parent link="world"/>
    <child link="plate_-1"/>
    <origin rpy="3.14159265359 0 0" xyz="0 0 1"/>
  </joint>
  <link name="plate_-1">
    <visual>
      <origin rpy="0 0 0" xyz="0 0 0"/>
      <geometry>
        <mesh filename="package://origarm_ros/model/mesh/origarmPlate_m.STL"/>
      </geometry>
      <material name="aluminum"/>
    </visual>
    <collision>
      <geometry>
        <cylinder length="0.005" radius="0.095"/>
      </geometry>
    </collision>
    <inertial>
      <origin rpy="0 0 0" xyz="0 0 0"/>
      <mass value="0.127"/>
      <inertia ixx="0.00032197" ixy="0.0" ixz="0.0" iyy="0.00032197" iyz="0.0" izz="0.00064284"/>
    </inertial>
  </link>
  <joint name="phantom_joint_segment_0_1_beta" type="revolute">
    <parent link="plate_-1"/>
    <child link="phantom_link_0_1"/>
    <axis xyz="0 0 1"/>
    <origin xyz="0 0 0"/>
    <limit effort="200" lower="-6.28318530718" upper="6.28318530718" velocity="20"/>
    <dynamics damping="0.7" friction="0.3"/>
  </joint>
  <link name="phantom_link_0_1">
    <visual>
      <geometry>
        <cylinder length="0.002" radius="0.005"/>
      </geometry>
      <origin rpy="0 0 0" xyz="0 0 0"/>
      <material name="blue"/>
    </visual>
    <inertial>
      <origin rpy="0 0 0" xyz="0 0 0"/>
      <mass value="0.01"/>
      <inertia ixx="0.001" ixy="0.0" ixz="0.0" iyy="0.001" iyz="0.0" izz="0.001"/>
    </inertial>
  </link>
  <joint name="phantom_joint_segment_0_2_alpha2" type="revolute">
    <parent link="phantom_link_0_1"/>
    <child link="phantom_link_0_2"/>
    <axis xyz="0 1 0"/>
    <origin xyz="0 0 0"/>
    <limit effort="200" lower="0.0" upper="0.25" velocity="20"/>
    <dynamics damping="0.7" friction="0.3"/>
  </joint>
  <link name="phantom_link_0_2">
    <visual>
      <geometry>
        <cylinder length="0.002" radius="0.005"/>
      </geometry>
      <origin rpy="0 0 0" xyz="0 0 0"/>
      <material name="blue"/>
    </visual>
    <inertial>
      <origin rpy="0 0 0" xyz="0 0 0"/>
      <mass value="0.01"/>
      <inertia ixx="0.001" ixy="0.0" ixz="0.0" iyy="0.001" iyz="0.0" izz="0.001"/>
    </inertial>
  </link>
  <joint name="phantom_joint_segment_0_3_translation" type="prismatic">
    <parent link="phantom_link_0_2"/>
    <child link="phantom_link_0_3"/>
    <axis xyz="0 0 1"/>
    <origin xyz="0 0 0.055"/>
    <limit effort="200" lower="-0.02" upper="0.03" velocity="20"/>
    <dynamics damping="0.7" friction="0.5"/>
  </joint>
  <link name="phantom_link_0_3">
    <visual>
      <geometry>
        <cylinder length="0.002" radius="0.005"/>
      </geometry>
      <origin rpy="0 0 0" xyz="0 0 0"/>
      <material name="blue"/>
    </visual>
    <inertial>
      <origin rpy="0 0 0" xyz="0 0 0"/>
      <mass value="0.01"/>
      <inertia ixx="0.001" ixy="0.0" ixz="0.0" iyy="0.001" iyz="0.0" izz="0.001"/>
    </inertial>
  </link>
  <joint name="phantom_joint_segment_0_4_alpha2" type="revolute">
    <parent link="phantom_link_0_3"/>
    <child link="phantom_link_0_4"/>
    <axis xyz="0 1 0"/>
    <origin xyz="0 0 0"/>
    <mimic joint="phantom_joint_segment_0_2_alpha2" multiplier="1" offset="0"/>
    <limit effort="200" lower="0.0" upper="0.25" velocity="20"/>
    <dynamics damping="0.7" friction="0.3"/>
  </joint>
  <link name="phantom_link_0_4">
    <visual>
      <geometry>
        <cylinder length="0.002" radius="0.005"/>
      </geometry>
      <origin rpy="0 0 0" xyz="0 0 0"/>
      <material name="blue"/>
    </visual>
    <inertial>
      <origin rpy="0 0 0" xyz="0 0 0"/>
      <mass value="0.01"/>
      <inertia ixx="0.001" ixy="0.0" ixz="0.0" iyy="0.001" iyz="0.0" izz="0.001"/>
    </inertial>
  </link>
  <joint name="phantom_joint_segment_0_5_betaN" type="revolute">
    <parent link="phantom_link_0_4"/>
    <child link="plate_0"/>
    <axis xyz="0 0 1"/>
    <origin xyz="0 0 0"/>
    <mimic joint="phantom_joint_segment_0_1_beta" multiplier="-1" offset="0"/>
    <limit effort="200" lower="-6.28318530718" upper="6.28318530718" velocity="20"/>
    <dynamics damping="0.7" friction="0.3"/>
  </joint>
  <link name="plate_0">
    <visual>
      <origin rpy="0 0 0" xyz="0 0 0"/>
      <geometry>
        <mesh filename="package://origarm_ros/model/mesh/origarmPlate_m.STL"/>
      </geometry>
      <material name="aluminum"/>
    </visual>
    <collision>
      <geometry>
        <cylinder length="0.005" radius="0.095"/>
      </geometry>
    </collision>
    <inertial>
      <origin rpy="0 0 0" xyz="0 0 0"/>
      <mass value="0.127"/>
      <inertia ixx="0.00032197" ixy="0.0" ixz="0.0" iyy="0.00032197" iyz="0.0" izz="0.00064284"/>
    </inertial>
  </link>
  <joint name="phantom_joint_segment_1_1_beta" type="revolute">
    <parent link="plate_0"/>
    <child link="phantom_link_1_1"/>
    <axis xyz="0 0 1"/>
    <origin xyz="0 0 0"/>
    <limit effort="200" lower="-6.28318530718" upper="6.28318530718" velocity="20"/>
    <dynamics damping="0.7" friction="0.3"/>
  </joint>
  <link name="phantom_link_1_1">
    <visual>
      <geometry>
        <cylinder length="0.002" radius="0.005"/>
      </geometry>
      <origin rpy="0 0 0" xyz="0 0 0"/>
      <material name="blue"/>
    </visual>
    <inertial>
      <origin rpy="0 0 0" xyz="0 0 0"/>
      <mass value="0.01"/>
      <inertia ixx="0.001" ixy="0.0" ixz="0.0" iyy="0.001" iyz="0.0" izz="0.001"/>
    </inertial>
  </link>
  <joint name="phantom_joint_segment_1_2_alpha2" type="revolute">
    <parent link="phantom_link_1_1"/>
    <child link="phantom_link_1_2"/>
    <axis xyz="0 1 0"/>
    <origin xyz="0 0 0"/>
    <limit effort="200" lower="0.0" upper="0.25" velocity="20"/>
    <dynamics damping="0.7" friction="0.3"/>
  </joint>
  <link name="phantom_link_1_2">
    <visual>
      <geometry>
        <cylinder length="0.002" radius="0.005"/>
      </geometry>
      <origin rpy="0 0 0" xyz="0 0 0"/>
      <material name="blue"/>
    </visual>
    <inertial>
      <origin rpy="0 0 0" xyz="0 0 0"/>
      <mass value="0.01"/>
      <inertia ixx="0.001" ixy="0.0" ixz="0.0" iyy="0.001" iyz="0.0" izz="0.001"/>
    </inertial>
  </link>
  <joint name="phantom_joint_segment_1_3_translation" type="prismatic">
    <parent link="phantom_link_1_2"/>
    <child link="phantom_link_1_3"/>
    <axis xyz="0 0 1"/>
    <origin xyz="0 0 0.055"/>
    <limit effort="200" lower="-0.02" upper="0.03" velocity="20"/>
    <dynamics damping="0.7" friction="0.5"/>
  </joint>
  <link name="phantom_link_1_3">
    <visual>
      <geometry>
        <cylinder length="0.002" radius="0.005"/>
      </geometry>
      <origin rpy="0 0 0" xyz="0 0 0"/>
      <material name="blue"/>
    </visual>
    <inertial>
      <origin rpy="0 0 0" xyz="0 0 0"/>
      <mass value="0.01"/>
      <inertia ixx="0.001" ixy="0.0" ixz="0.0" iyy="0.001" iyz="0.0" izz="0.001"/>
    </inertial>
  </link>
  <joint name="phantom_joint_segment_1_4_alpha2" type="revolute">
    <parent link="phantom_link_1_3"/>
    <child link="phantom_link_1_4"/>
    <axis xyz="0 1 0"/>
    <origin xyz="0 0 0"/>
    <mimic joint="phantom_joint_segment_1_2_alpha2" multiplier="1" offset="0"/>
    <limit effort="200" lower="0.0" upper="0.25" velocity="20"/>
    <dynamics damping="0.7" friction="0.3"/>
  </joint>
  <link name="phantom_link_1_4">
    <visual>
      <geometry>
        <cylinder length="0.002" radius="0.005"/>
      </geometry>
      <origin rpy="0 0 0" xyz="0 0 0"/>
      <material name="blue"/>
    </visual>
    <inertial>
      <origin rpy="0 0 0" xyz="0 0 0"/>
      <mass value="0.01"/>
      <inertia ixx="0.001" ixy="0.0" ixz="0.0" iyy="0.001" iyz="0.0" izz="0.001"/>
    </inertial>
  </link>
  <joint name="phantom_joint_segment_1_5_betaN" type="revolute">
    <parent link="phantom_link_1_4"/>
    <child link="plate_1"/>
    <axis xyz="0 0 1"/>
    <origin xyz="0 0 0"/>
    <mimic joint="phantom_joint_segment_1_1_beta" multiplier="-1" offset="0"/>
    <limit effort="200" lower="-6.28318530718" upper="6.28318530718" velocity="20"/>
    <dynamics damping="0.7" friction="0.3"/>
  </joint>
  <link name="plate_1">
    <visual>
      <origin rpy="0 0 0" xyz="0 0 0"/>
      <geometry>
        <mesh filename="package://origarm_ros/model/mesh/origarmPlate_m.STL"/>
      </geometry>
      <material name="aluminum"/>
    </visual>
    <collision>
      <geometry>
        <cylinder length="0.005" radius="0.095"/>
      </geometry>
    </collision>
    <inertial>
      <origin rpy="0 0 0" xyz="0 0 0"/>
      <mass value="0.127"/>
      <inertia ixx="0.00032197" ixy="0.0" ixz="0.0" iyy="0.00032197" iyz="0.0" izz="0.00064284"/>
    </inertial>
  </link>
  <joint name="phantom_joint_segment_2_1_beta" type="revolute">
    <parent link="plate_1"/>
    <child link="phantom_link_2_1"/>
    <axis xyz="0 0 1"/>
    <origin xyz="0 0 0"/>
    <limit effort="200" lower="-6.28318530718" upper="6.28318530718" velocity="20"/>
    <dynamics damping="0.7" friction="0.3"/>
  </joint>
  <link name="phantom_link_2_1">
    <visual>
      <geometry>
        <cylinder length="0.002" radius="0.005"/>
      </geometry>
      <origin rpy="0 0 0" xyz="0 0 0"/>
      <material name="blue"/>
    </visual>
    <inertial>
      <origin rpy="0 0 0" xyz="0 0 0"/>
      <mass value="0.01"/>
      <inertia ixx="0.001" ixy="0.0" ixz="0.0" iyy="0.001" iyz="0.0" izz="0.001"/>
    </inertial>
  </link>
  <joint name="phantom_joint_segment_2_2_alpha2" type="revolute">
    <parent link="phantom_link_2_1"/>
    <child link="phantom_link_2_2"/>
    <axis xyz="0 1 0"/>
    <origin xyz="0 0 0"/>
    <limit effort="200" lower="0.0" upper="0.25" velocity="20"/>
    <dynamics damping="0.7" friction="0.3"/>
  </joint>
  <link name="phantom_link_2_2">
    <visual>
      <geometry>
        <cylinder length="0.002" radius="0.005"/>
      </geometry>
      <origin rpy="0 0 0" xyz="0 0 0"/>
      <material name="blue"/>
    </visual>
    <inertial>
      <origin rpy="0 0 0" xyz="0 0 0"/>
      <mass value="0.01"/>
      <inertia ixx="0.001" ixy="0.0" ixz="0.0" iyy="0.001" iyz="0.0" izz="0.001"/>
    </inertial>
  </link>
  <joint name="phantom_joint_segment_2_3_translation" type="prismatic">
    <parent link="phantom_link_2_2"/>
    <child link="phantom_link_2_3"/>
    <axis xyz="0 0 1"/>
    <origin xyz="0 0 0.055"/>
    <limit effort="200" lower="-0.02" upper="0.03" velocity="20"/>
    <dynamics damping="0.7" friction="0.5"/>
  </joint>
  <link name="phantom_link_2_3">
    <visual>
      <geometry>
        <cylinder length="0.002" radius="0.005"/>
      </geometry>
      <origin rpy="0 0 0" xyz="0 0 0"/>
      <material name="blue"/>
    </visual>
    <inertial>
      <origin rpy="0 0 0" xyz="0 0 0"/>
      <mass value="0.01"/>
      <inertia ixx="0.001" ixy="0.0" ixz="0.0" iyy="0.001" iyz="0.0" izz="0.001"/>
    </inertial>
  </link>
  <joint name="phantom_joint_segment_2_4_alpha2" type="revolute">
    <parent link="phantom_link_2_3"/>
    <child link="phantom_link_2_4"/>
    <axis xyz="0 1 0"/>
    <origin xyz="0 0 0"/>
    <mimic joint="phantom_joint_segment_2_2_alpha2" multiplier="1" offset="0"/>
    <limit effort="200" lower="0.0" upper="0.25" velocity="20"/>
    <dynamics damping="0.7" friction="0.3"/>
  </joint>
  <link name="phantom_link_2_4">
    <visual>
      <geometry>
        <cylinder length="0.002" radius="0.005"/>
      </geometry>
      <origin rpy="0 0 0" xyz="0 0 0"/>
      <material name="blue"/>
    </visual>
    <inertial>
      <origin rpy="0 0 0" xyz="0 0 0"/>
      <mass value="0.01"/>
      <inertia ixx="0.001" ixy="0.0" ixz="0.0" iyy="0.001" iyz="0.0" izz="0.001"/>
    </inertial>
  </link>
  <joint name="phantom_joint_segment_2_5_betaN" type="revolute">
    <parent link="phantom_link_2_4"/>
    <child link="plate_2"/>
    <axis xyz="0 0 1"/>
    <origin xyz="0 0 0"/>
    <mimic joint="phantom_joint_segment_2_1_beta" multiplier="-1" offset="0"/>
    <limit effort="200" lower="-6.28318530718" upper="6.28318530718" velocity="20"/>
    <dynamics damping="0.7" friction="0.3"/>
  </joint>
  <link name="plate_2">
    <visual>
      <origin rpy="0 0 0" xyz="0 0 0"/>
      <geometry>
        <mesh filename="package://origarm_ros/model/mesh/origarmPlate_m.STL"/>
      </geometry>
      <material name="aluminum"/>
    </visual>
    <collision>
      <geometry>
        <cylinder length="0.005" radius="0.095"/>
      </geometry>
    </collision>
    <inertial>
      <origin rpy="0 0 0" xyz="0 0 0"/>
      <mass value="0.127"/>
      <inertia ixx="0.00032197" ixy="0.0" ixz="0.0" iyy="0.00032197" iyz="0.0" izz="0.00064284"/>
    </inertial>
  </link>
  <joint name="phantom_joint_segment_3_1_beta" type="revolute">
    <parent link="plate_2"/>
    <child link="phantom_link_3_1"/>
    <axis xyz="0 0 1"/>
    <origin xyz="0 0 0"/>
    <limit effort="200" lower="-6.28318530718" upper="6.28318530718" velocity="20"/>
    <dynamics damping="0.7" friction="0.3"/>
  </joint>
  <link name="phantom_link_3_1">
    <visual>
      <geometry>
        <cylinder length="0.002" radius="0.005"/>
      </geometry>
      <origin rpy="0 0 0" xyz="0 0 0"/>
      <material name="blue"/>
    </visual>
    <inertial>
      <origin rpy="0 0 0" xyz="0 0 0"/>
      <mass value="0.01"/>
      <inertia ixx="0.001" ixy="0.0" ixz="0.0" iyy="0.001" iyz="0.0" izz="0.001"/>
    </inertial>
  </link>
  <joint name="phantom_joint_segment_3_2_alpha2" type="revolute">
    <parent link="phantom_link_3_1"/>
    <child link="phantom_link_3_2"/>
    <axis xyz="0 1 0"/>
    <origin xyz="0 0 0"/>
    <limit effort="200" lower="0.0" upper="0.25" velocity="20"/>
    <dynamics damping="0.7" friction="0.3"/>
  </joint>
  <link name="phantom_link_3_2">
    <visual>
      <geometry>
        <cylinder length="0.002" radius="0.005"/>
      </geometry>
      <origin rpy="0 0 0" xyz="0 0 0"/>
      <material name="blue"/>
    </visual>
    <inertial>
      <origin rpy="0 0 0" xyz="0 0 0"/>
      <mass value="0.01"/>
      <inertia ixx="0.001" ixy="0.0" ixz="0.0" iyy="0.001" iyz="0.0" izz="0.001"/>
    </inertial>
  </link>
  <joint name="phantom_joint_segment_3_3_translation" type="prismatic">
    <parent link="phantom_link_3_2"/>
    <child link="phantom_link_3_3"/>
    <axis xyz="0 0 1"/>
    <origin xyz="0 0 0.055"/>
    <limit effort="200" lower="-0.02" upper="0.03" velocity="20"/>
    <dynamics damping="0.7" friction="0.5"/>
  </joint>
  <link name="phantom_link_3_3">
    <visual>
      <geometry>
        <cylinder length="0.002" radius="0.005"/>
      </geometry>
      <origin rpy="0 0 0" xyz="0 0 0"/>
      <material name="blue"/>
    </visual>
    <inertial>
      <origin rpy="0 0 0" xyz="0 0 0"/>
      <mass value="0.01"/>
      <inertia ixx="0.001" ixy="0.0" ixz="0.0" iyy="0.001" iyz="0.0" izz="0.001"/>
    </inertial>
  </link>
  <joint name="phantom_joint_segment_3_4_alpha2" type="revolute">
    <parent link="phantom_link_3_3"/>
    <child link="phantom_link_3_4"/>
    <axis xyz="0 1 0"/>
    <origin xyz="0 0 0"/>
    <mimic joint="phantom_joint_segment_3_2_alpha2" multiplier="1" offset="0"/>
    <limit effort="200" lower="0.0" upper="0.25" velocity="20"/>
    <dynamics damping="0.7" friction="0.3"/>
  </joint>
  <link name="phantom_link_3_4">
    <visual>
      <geometry>
        <cylinder length="0.002" radius="0.005"/>
      </geometry>
      <origin rpy="0 0 0" xyz="0 0 0"/>
      <material name="blue"/>
    </visual>
    <inertial>
      <origin rpy="0 0 0" xyz="0 0 0"/>
      <mass value="0.01"/>
      <inertia ixx="0.001" ixy="0.0" ixz="0.0" iyy="0.001" iyz="0.0" izz="0.001"/>
    </inertial>
  </link>
  <joint name="phantom_joint_segment_3_5_betaN" type="revolute">
    <parent link="phantom_link_3_4"/>
    <child link="plate_3"/>
    <axis xyz="0 0 1"/>
    <origin xyz="0 0 0"/>
    <mimic joint="phantom_joint_segment_3_1_beta" multiplier="-1" offset="0"/>
    <limit effort="200" lower="-6.28318530718" upper="6.28318530718" velocity="20"/>
    <dynamics damping="0.7" friction="0.3"/>
  </joint>
  <link name="plate_3">
    <visual>
      <origin rpy="0 0 0" xyz="0 0 0"/>
      <geometry>
        <mesh filename="package://origarm_ros/model/mesh/origarmPlate_m.STL"/>
      </geometry>
      <material name="aluminum"/>
    </visual>
    <collision>
      <geometry>
        <cylinder length="0.005" radius="0.095"/>
      </geometry>
    </collision>
    <inertial>
      <origin rpy="0 0 0" xyz="0 0 0"/>
      <mass value="0.127"/>
      <inertia ixx="0.00032197" ixy="0.0" ixz="0.0" iyy="0.00032197" iyz="0.0" izz="0.00064284"/>
    </inertial>
  </link>
  <joint name="phantom_joint_segment_4_1_beta" type="revolute">
    <parent link="plate_3"/>
    <child link="phantom_link_4_1"/>
    <axis xyz="0 0 1"/>
    <origin xyz="0 0 0"/>
    <limit effort="200" lower="-6.28318530718" upper="6.28318530718" velocity="20"/>
    <dynamics damping="0.7" friction="0.3"/>
  </joint>
  <link name="phantom_link_4_1">
    <visual>
      <geometry>
        <cylinder length="0.002" radius="0.005"/>
      </geometry>
      <origin rpy="0 0 0" xyz="0 0 0"/>
      <material name="blue"/>
    </visual>
    <inertial>
      <origin rpy="0 0 0" xyz="0 0 0"/>
      <mass value="0.01"/>
      <inertia ixx="0.001" ixy="0.0" ixz="0.0" iyy="0.001" iyz="0.0" izz="0.001"/>
    </inertial>
  </link>
  <joint name="phantom_joint_segment_4_2_alpha2" type="revolute">
    <parent link="phantom_link_4_1"/>
    <child link="phantom_link_4_2"/>
    <axis xyz="0 1 0"/>
    <origin xyz="0 0 0"/>
    <limit effort="200" lower="0.0" upper="0.25" velocity="20"/>
    <dynamics damping="0.7" friction="0.3"/>
  </joint>
  <link name="phantom_link_4_2">
    <visual>
      <geometry>
        <cylinder length="0.002" radius="0.005"/>
      </geometry>
      <origin rpy="0 0 0" xyz="0 0 0"/>
      <material name="blue"/>
    </visual>
    <inertial>
      <origin rpy="0 0 0" xyz="0 0 0"/>
      <mass value="0.01"/>
      <inertia ixx="0.001" ixy="0.0" ixz="0.0" iyy="0.001" iyz="0.0" izz="0.001"/>
    </inertial>
  </link>
  <joint name="phantom_joint_segment_4_3_translation" type="prismatic">
    <parent link="phantom_link_4_2"/>
    <child link="phantom_link_4_3"/>
    <axis xyz="0 0 1"/>
    <origin xyz="0 0 0.055"/>
    <limit effort="200" lower="-0.02" upper="0.03" velocity="20"/>
    <dynamics damping="0.7" friction="0.5"/>
  </joint>
  <link name="phantom_link_4_3">
    <visual>
      <geometry>
        <cylinder length="0.002" radius="0.005"/>
      </geometry>
      <origin rpy="0 0 0" xyz="0 0 0"/>
      <material name="blue"/>
    </visual>
    <inertial>
      <origin rpy="0 0 0" xyz="0 0 0"/>
      <mass value="0.01"/>
      <inertia ixx="0.001" ixy="0.0" ixz="0.0" iyy="0.001" iyz="0.0" izz="0.001"/>
    </inertial>
  </link>
  <joint name="phantom_joint_segment_4_4_alpha2" type="revolute">
    <parent link="phantom_link_4_3"/>
    <child link="phantom_link_4_4"/>
    <axis xyz="0 1 0"/>
    <origin xyz="0 0 0"/>
    <mimic joint="phantom_joint_segment_4_2_alpha2" multiplier="1" offset="0"/>
    <limit effort="200" lower="0.0" upper="0.25" velocity="20"/>
    <dynamics damping="0.7" friction="0.3"/>
  </joint>
  <link name="phantom_link_4_4">
    <visual>
      <geometry>
        <cylinder length="0.002" radius="0.005"/>
      </geometry>
      <origin rpy="0 0 0" xyz="0 0 0"/>
      <material name="blue"/>
    </visual>
    <inertial>
      <origin rpy="0 0 0" xyz="0 0 0"/>
      <mass value="0.01"/>
      <inertia ixx="0.001" ixy="0.0" ixz="0.0" iyy="0.001" iyz="0.0" izz="0.001"/>
    </inertial>
  </link>
  <joint name="phantom_joint_segment_4_5_betaN" type="revolute">
    <parent link="phantom_link_4_4"/>
    <child link="plate_4"/>
    <axis xyz="0 0 1"/>
    <origin xyz="0 0 0"/>
    <mimic joint="phantom_joint_segment_4_1_beta" multiplier="-1" offset="0"/>
    <limit effort="200" lower="-6.28318530718" upper="6.28318530718" velocity="20"/>
    <dynamics damping="0.7" friction="0.3"/>
  </joint>
  <link name="plate_4">
    <visual>
      <origin rpy="0 0 0" xyz="0 0 0"/>
      <geometry>
        <mesh filename="package://origarm_ros/model/mesh/origarmPlate_m.STL"/>
      </geometry>
      <material name="aluminum"/>
    </visual>
    <collision>
      <geometry>
        <cylinder length="0.005" radius="0.095"/>
      </geometry>
    </collision>
    <inertial>
      <origin rpy="0 0 0" xyz="0 0 0"/>
      <mass value="0.127"/>
      <inertia ixx="0.00032197" ixy="0.0" ixz="0.0" iyy="0.00032197" iyz="0.0" izz="0.00064284"/>
    </inertial>
  </link>
  <joint name="phantom_joint_segment_5_1_beta" type="revolute">
    <parent link="plate_4"/>
    <child link="phantom_link_5_1"/>
    <axis xyz="0 0 1"/>
    <origin xyz="0 0 0"/>
    <limit effort="200" lower="-6.28318530718" upper="6.28318530718" velocity="20"/>
    <dynamics damping="0.7" friction="0.3"/>
  </joint>
  <link name="phantom_link_5_1">
    <visual>
      <geometry>
        <cylinder length="0.002" radius="0.005"/>
      </geometry>
      <origin rpy="0 0 0" xyz="0 0 0"/>
      <material name="blue"/>
    </visual>
    <inertial>
      <origin rpy="0 0 0" xyz="0 0 0"/>
      <mass value="0.01"/>
      <inertia ixx="0.001" ixy="0.0" ixz="0.0" iyy="0.001" iyz="0.0" izz="0.001"/>
    </inertial>
  </link>
  <joint name="phantom_joint_segment_5_2_alpha2" type="revolute">
    <parent link="phantom_link_5_1"/>
    <child link="phantom_link_5_2"/>
    <axis xyz="0 1 0"/>
    <origin xyz="0 0 0"/>
    <limit effort="200" lower="0.0" upper="0.25" velocity="20"/>
    <dynamics damping="0.7" friction="0.3"/>
  </joint>
  <link name="phantom_link_5_2">
    <visual>
      <geometry>
        <cylinder length="0.002" radius="0.005"/>
      </geometry>
      <origin rpy="0 0 0" xyz="0 0 0"/>
      <material name="blue"/>
    </visual>
    <inertial>
      <origin rpy="0 0 0" xyz="0 0 0"/>
      <mass value="0.01"/>
      <inertia ixx="0.001" ixy="0.0" ixz="0.0" iyy="0.001" iyz="0.0" izz="0.001"/>
    </inertial>
  </link>
  <joint name="phantom_joint_segment_5_3_translation" type="prismatic">
    <parent link="phantom_link_5_2"/>
    <child link="phantom_link_5_3"/>
    <axis xyz="0 0 1"/>
    <origin xyz="0 0 0.055"/>
    <limit effort="200" lower="-0.02" upper="0.03" velocity="20"/>
    <dynamics damping="0.7" friction="0.5"/>
  </joint>
  <link name="phantom_link_5_3">
    <visual>
      <geometry>
        <cylinder length="0.002" radius="0.005"/>
      </geometry>
      <origin rpy="0 0 0" xyz="0 0 0"/>
      <material name="blue"/>
    </visual>
    <inertial>
      <origin rpy="0 0 0" xyz="0 0 0"/>
      <mass value="0.01"/>
      <inertia ixx="0.001" ixy="0.0" ixz="0.0" iyy="0.001" iyz="0.0" izz="0.001"/>
    </inertial>
  </link>
  <joint name="phantom_joint_segment_5_4_alpha2" type="revolute">
    <parent link="phantom_link_5_3"/>
    <child link="phantom_link_5_4"/>
    <axis xyz="0 1 0"/>
    <origin xyz="0 0 0"/>
    <mimic joint="phantom_joint_segment_5_2_alpha2" multiplier="1" offset="0"/>
    <limit effort="200" lower="0.0" upper="0.25" velocity="20"/>
    <dynamics damping="0.7" friction="0.3"/>
  </joint>
  <link name="phantom_link_5_4">
    <visual>
      <geometry>
        <cylinder length="0.002" radius="0.005"/>
      </geometry>
      <origin rpy="0 0 0" xyz="0 0 0"/>
      <material name="blue"/>
    </visual>
    <inertial>
      <origin rpy="0 0 0" xyz="0 0 0"/>
      <mass value="0.01"/>
      <inertia ixx="0.001" ixy="0.0" ixz="0.0" iyy="0.001" iyz="0.0" izz="0.001"/>
    </inertial>
  </link>
  <joint name="phantom_joint_segment_5_5_betaN" type="revolute">
    <parent link="phantom_link_5_4"/>
    <child link="plate_5"/>
    <axis xyz="0 0 1"/>
    <origin xyz="0 0 0"/>
    <mimic joint="phantom_joint_segment_5_1_beta" multiplier="-1" offset="0"/>
    <limit effort="200" lower="-6.28318530718" upper="6.28318530718" velocity="20"/>
    <dynamics damping="0.7" friction="0.3"/>
  </joint>
  <link name="plate_5">
    <visual>
      <origin rpy="0 0 0" xyz="0 0 0"/>
      <geometry>
        <mesh filename="package://origarm_ros/model/mesh/origarmPlate_m.STL"/>
      </geometry>
      <material name="aluminum"/>
    </visual>
    <collision>
      <geometry>
        <cylinder length="0.005" radius="0.095"/>
      </geometry>
    </collision>
    <inertial>
      <origin rpy="0 0 0" xyz="0 0 0"/>
      <mass value="0.127"/>
      <inertia ixx="0.00032197" ixy="0.0" ixz="0.0" iyy="0.00032197" iyz="0.0" izz="0.00064284"/>
    </inertial>
  </link>
  <!-- ros_control plugin      -->
  <!-- Add gazebo transmission -->
  <gazebo>
    <plugin filename="libgazebo_ros_control.so" name="gazebo_ros_control">
      <robotNamespace>/origarmRigidKE</robotNamespace>
    </plugin>
  </gazebo>
  <transmission name="trans_segment_0_1_beta">
    <type>transmission_interface/SimpleTransmission</type>
    <joint name="phantom_joint_segment_0_1_beta">
      <hardwareInterface>hardware_interface/PositionJointInterface</hardwareInterface>
    </joint>
    <actuator name="actuator_segment_0_1_beta">
      <hardwareInterface>hardware_interface/PositionJointInterface</hardwareInterface>
      <mechanicalReduction>1</mechanicalReduction>
    </actuator>
  </transmission>
  <transmission name="trans_segment_0_2_alpha2">
    <type>transmission_interface/SimpleTransmission</type>
    <joint name="phantom_joint_segment_0_2_alpha2">
      <hardwareInterface>hardware_interface/PositionJointInterface</hardwareInterface>
    </joint>
    <actuator name="actuator_segment_0_2_alpha2">
      <hardwareInterface>hardware_interface/PositionJointInterface</hardwareInterface>
      <mechanicalReduction>1</mechanicalReduction>
    </actuator>
  </transmission>
  <transmission name="trans_segment_0_3_translation">
    <type>transmission_interface/SimpleTransmission</type>
    <joint name="phantom_joint_segment_0_3_translation">
      <hardwareInterface>hardware_interface/PositionJointInterface</hardwareInterface>
    </joint>
    <actuator name="actuator_segment_0_3_translation">
      <hardwareInterface>hardware_interface/PositionJointInterface</hardwareInterface>
      <mechanicalReduction>1</mechanicalReduction>
    </actuator>
  </transmission>
  <transmission name="trans_segment_0_4_alpha2">
    <type>transmission_interface/SimpleTransmission</type>
    <joint name="phantom_joint_segment_0_4_alpha2">
      <hardwareInterface>hardware_interface/PositionJointInterface</hardwareInterface>
    </joint>
    <actuator name="actuator_segment_0_4_alpha2">
      <hardwareInterface>hardware_interface/PositionJointInterface</hardwareInterface>
      <mechanicalReduction>1</mechanicalReduction>
    </actuator>
  </transmission>
  <transmission name="trans_segment_0_5_betaN">
    <type>transmission_interface/SimpleTransmission</type>
    <joint name="phantom_joint_segment_0_5_betaN">
      <hardwareInterface>hardware_interface/PositionJointInterface</hardwareInterface>
    </joint>
    <actuator name="actuator_segment_0_5_betaN">
      <hardwareInterface>hardware_interface/PositionJointInterface</hardwareInterface>
      <mechanicalReduction>1</mechanicalReduction>
    </actuator>
  </transmission>
  <transmission name="trans_segment_1_1_beta">
    <type>transmission_interface/SimpleTransmission</type>
    <joint name="phantom_joint_segment_1_1_beta">
      <hardwareInterface>hardware_interface/PositionJointInterface</hardwareInterface>
    </joint>
    <actuator name="actuator_segment_1_1_beta">
      <hardwareInterface>hardware_interface/PositionJointInterface</hardwareInterface>
      <mechanicalReduction>1</mechanicalReduction>
    </actuator>
  </transmission>
  <transmission name="trans_segment_1_2_alpha2">
    <type>transmission_interface/SimpleTransmission</type>
    <joint name="phantom_joint_segment_1_2_alpha2">
      <hardwareInterface>hardware_interface/PositionJointInterface</hardwareInterface>
    </joint>
    <actuator name="actuator_segment_1_2_alpha2">
      <hardwareInterface>hardware_interface/PositionJointInterface</hardwareInterface>
      <mechanicalReduction>1</mechanicalReduction>
    </actuator>
  </transmission>
  <transmission name="trans_segment_1_3_translation">
    <type>transmission_interface/SimpleTransmission</type>
    <joint name="phantom_joint_segment_1_3_translation">
      <hardwareInterface>hardware_interface/PositionJointInterface</hardwareInterface>
    </joint>
    <actuator name="actuator_segment_1_3_translation">
      <hardwareInterface>hardware_interface/PositionJointInterface</hardwareInterface>
      <mechanicalReduction>1</mechanicalReduction>
    </actuator>
  </transmission>
  <transmission name="trans_segment_1_4_alpha2">
    <type>transmission_interface/SimpleTransmission</type>
    <joint name="phantom_joint_segment_1_4_alpha2">
      <hardwareInterface>hardware_interface/PositionJointInterface</hardwareInterface>
    </joint>
    <actuator name="actuator_segment_1_4_alpha2">
      <hardwareInterface>hardware_interface/PositionJointInterface</hardwareInterface>
      <mechanicalReduction>1</mechanicalReduction>
    </actuator>
  </transmission>
  <transmission name="trans_segment_1_5_betaN">
    <type>transmission_interface/SimpleTransmission</type>
    <joint name="phantom_joint_segment_1_5_betaN">
      <hardwareInterface>hardware_interface/PositionJointInterface</hardwareInterface>
    </joint>
    <actuator name="actuator_segment_1_5_betaN">
      <hardwareInterface>hardware_interface/PositionJointInterface</hardwareInterface>
      <mechanicalReduction>1</mechanicalReduction>
    </actuator>
  </transmission>
  <transmission name="trans_segment_2_1_beta">
    <type>transmission_interface/SimpleTransmission</type>
    <joint name="phantom_joint_segment_2_1_beta">
      <hardwareInterface>hardware_interface/PositionJointInterface</hardwareInterface>
    </joint>
    <actuator name="actuator_segment_2_1_beta">
      <hardwareInterface>hardware_interface/PositionJointInterface</hardwareInterface>
      <mechanicalReduction>1</mechanicalReduction>
    </actuator>
  </transmission>
  <transmission name="trans_segment_2_2_alpha2">
    <type>transmission_interface/SimpleTransmission</type>
    <joint name="phantom_joint_segment_2_2_alpha2">
      <hardwareInterface>hardware_interface/PositionJointInterface</hardwareInterface>
    </joint>
    <actuator name="actuator_segment_2_2_alpha2">
      <hardwareInterface>hardware_interface/PositionJointInterface</hardwareInterface>
      <mechanicalReduction>1</mechanicalReduction>
    </actuator>
  </transmission>
  <transmission name="trans_segment_2_3_translation">
    <type>transmission_interface/SimpleTransmission</type>
    <joint name="phantom_joint_segment_2_3_translation">
      <hardwareInterface>hardware_interface/PositionJointInterface</hardwareInterface>
    </joint>
    <actuator name="actuator_segment_2_3_translation">
      <hardwareInterface>hardware_interface/PositionJointInterface</hardwareInterface>
      <mechanicalReduction>1</mechanicalReduction>
    </actuator>
  </transmission>
  <transmission name="trans_segment_2_4_alpha2">
    <type>transmission_interface/SimpleTransmission</type>
    <joint name="phantom_joint_segment_2_4_alpha2">
      <hardwareInterface>hardware_interface/PositionJointInterface</hardwareInterface>
    </joint>
    <actuator name="actuator_segment_2_4_alpha2">
      <hardwareInterface>hardware_interface/PositionJointInterface</hardwareInterface>
      <mechanicalReduction>1</mechanicalReduction>
    </actuator>
  </transmission>
  <transmission name="trans_segment_2_5_betaN">
    <type>transmission_interface/SimpleTransmission</type>
    <joint name="phantom_joint_segment_2_5_betaN">
      <hardwareInterface>hardware_interface/PositionJointInterface</hardwareInterface>
    </joint>
    <actuator name="actuator_segment_2_5_betaN">
      <hardwareInterface>hardware_interface/PositionJointInterface</hardwareInterface>
      <mechanicalReduction>1</mechanicalReduction>
    </actuator>
  </transmission>
  <transmission name="trans_segment_3_1_beta">
    <type>transmission_interface/SimpleTransmission</type>
    <joint name="phantom_joint_segment_3_1_beta">
      <hardwareInterface>hardware_interface/PositionJointInterface</hardwareInterface>
    </joint>
    <actuator name="actuator_segment_3_1_beta">
      <hardwareInterface>hardware_interface/PositionJointInterface</hardwareInterface>
      <mechanicalReduction>1</mechanicalReduction>
    </actuator>
  </transmission>
  <transmission name="trans_segment_3_2_alpha2">
    <type>transmission_interface/SimpleTransmission</type>
    <joint name="phantom_joint_segment_3_2_alpha2">
      <hardwareInterface>hardware_interface/PositionJointInterface</hardwareInterface>
    </joint>
    <actuator name="actuator_segment_3_2_alpha2">
      <hardwareInterface>hardware_interface/PositionJointInterface</hardwareInterface>
      <mechanicalReduction>1</mechanicalReduction>
    </actuator>
  </transmission>
  <transmission name="trans_segment_3_3_translation">
    <type>transmission_interface/SimpleTransmission</type>
    <joint name="phantom_joint_segment_3_3_translation">
      <hardwareInterface>hardware_interface/PositionJointInterface</hardwareInterface>
    </joint>
    <actuator name="actuator_segment_3_3_translation">
      <hardwareInterface>hardware_interface/PositionJointInterface</hardwareInterface>
      <mechanicalReduction>1</mechanicalReduction>
    </actuator>
  </transmission>
  <transmission name="trans_segment_3_4_alpha2">
    <type>transmission_interface/SimpleTransmission</type>
    <joint name="phantom_joint_segment_3_4_alpha2">
      <hardwareInterface>hardware_interface/PositionJointInterface</hardwareInterface>
    </joint>
    <actuator name="actuator_segment_3_4_alpha2">
      <hardwareInterface>hardware_interface/PositionJointInterface</hardwareInterface>
      <mechanicalReduction>1</mechanicalReduction>
    </actuator>
  </transmission>
  <transmission name="trans_segment_3_5_betaN">
    <type>transmission_interface/SimpleTransmission</type>
    <joint name="phantom_joint_segment_3_5_betaN">
      <hardwareInterface>hardware_interface/PositionJointInterface</hardwareInterface>
    </joint>
    <actuator name="actuator_segment_3_5_betaN">
      <hardwareInterface>hardware_interface/PositionJointInterface</hardwareInterface>
      <mechanicalReduction>1</mechanicalReduction>
    </actuator>
  </transmission>
  <transmission name="trans_segment_4_1_beta">
    <type>transmission_interface/SimpleTransmission</type>
    <joint name="phantom_joint_segment_4_1_beta">
      <hardwareInterface>hardware_interface/PositionJointInterface</hardwareInterface>
    </joint>
    <actuator name="actuator_segment_4_1_beta">
      <hardwareInterface>hardware_interface/PositionJointInterface</hardwareInterface>
      <mechanicalReduction>1</mechanicalReduction>
    </actuator>
  </transmission>
  <transmission name="trans_segment_4_2_alpha2">
    <type>transmission_interface/SimpleTransmission</type>
    <joint name="phantom_joint_segment_4_2_alpha2">
      <hardwareInterface>hardware_interface/PositionJointInterface</hardwareInterface>
    </joint>
    <actuator name="actuator_segment_4_2_alpha2">
      <hardwareInterface>hardware_interface/PositionJointInterface</hardwareInterface>
      <mechanicalReduction>1</mechanicalReduction>
    </actuator>
  </transmission>
  <transmission name="trans_segment_4_3_translation">
    <type>transmission_interface/SimpleTransmission</type>
    <joint name="phantom_joint_segment_4_3_translation">
      <hardwareInterface>hardware_interface/PositionJointInterface</hardwareInterface>
    </joint>
    <actuator name="actuator_segment_4_3_translation">
      <hardwareInterface>hardware_interface/PositionJointInterface</hardwareInterface>
      <mechanicalReduction>1</mechanicalReduction>
    </actuator>
  </transmission>
  <transmission name="trans_segment_4_4_alpha2">
    <type>transmission_interface/SimpleTransmission</type>
    <joint name="phantom_joint_segment_4_4_alpha2">
      <hardwareInterface>hardware_interface/PositionJointInterface</hardwareInterface>
    </joint>
    <actuator name="actuator_segment_4_4_alpha2">
      <hardwareInterface>hardware_interface/PositionJointInterface</hardwareInterface>
      <mechanicalReduction>1</mechanicalReduction>
    </actuator>
  </transmission>
  <transmission name="trans_segment_4_5_betaN">
    <type>transmission_interface/SimpleTransmission</type>
    <joint name="phantom_joint_segment_4_5_betaN">
      <hardwareInterface>hardware_interface/PositionJointInterface</hardwareInterface>
    </joint>
    <actuator name="actuator_segment_4_5_betaN">
      <hardwareInterface>hardware_interface/PositionJointInterface</hardwareInterface>
      <mechanicalReduction>1</mechanicalReduction>
    </actuator>
  </transmission>
  <transmission name="trans_segment_5_1_beta">
    <type>transmission_interface/SimpleTransmission</type>
    <joint name="phantom_joint_segment_5_1_beta">
      <hardwareInterface>hardware_interface/PositionJointInterface</hardwareInterface>
    </joint>
    <actuator name="actuator_segment_5_1_beta">
      <hardwareInterface>hardware_interface/PositionJointInterface</hardwareInterface>
      <mechanicalReduction>1</mechanicalReduction>
    </actuator>
  </transmission>
  <transmission name="trans_segment_5_2_alpha2">
    <type>transmission_interface/SimpleTransmission</type>
    <joint name="phantom_joint_segment_5_2_alpha2">
      <hardwareInterface>hardware_interface/PositionJointInterface</hardwareInterface>
    </joint>
    <actuator name="actuator_segment_5_2_alpha2">
      <hardwareInterface>hardware_interface/PositionJointInterface</hardwareInterface>
      <mechanicalReduction>1</mechanicalReduction>
    </actuator>
  </transmission>
  <transmission name="trans_segment_5_3_translation">
    <type>transmission_interface/SimpleTransmission</type>
    <joint name="phantom_joint_segment_5_3_translation">
      <hardwareInterface>hardware_interface/PositionJointInterface</hardwareInterface>
    </joint>
    <actuator name="actuator_segment_5_3_translation">
      <hardwareInterface>hardware_interface/PositionJointInterface</hardwareInterface>
      <mechanicalReduction>1</mechanicalReduction>
    </actuator>
  </transmission>
  <transmission name="trans_segment_5_4_alpha2">
    <type>transmission_interface/SimpleTransmission</type>
    <joint name="phantom_joint_segment_5_4_alpha2">
      <hardwareInterface>hardware_interface/PositionJointInterface</hardwareInterface>
    </joint>
    <actuator name="actuator_segment_5_4_alpha2">
      <hardwareInterface>hardware_interface/PositionJointInterface</hardwareInterface>
      <mechanicalReduction>1</mechanicalReduction>
    </actuator>
  </transmission>
  <transmission name="trans_segment_5_5_betaN">
    <type>transmission_interface/SimpleTransmission</type>
    <joint name="phantom_joint_segment_5_5_betaN">
      <hardwareInterface>hardware_interface/PositionJointInterface</hardwareInterface>
    </joint>
    <actuator name="actuator_segment_5_5_betaN">
      <hardwareInterface>hardware_interface/PositionJointInterface</hardwareInterface>
      <mechanicalReduction>1</mechanicalReduction>
    </actuator>
  </transmission>
  <gazebo reference="phantom_link_0_0">
    <gravity>false</gravity>
    <dampingFactor>0.1</dampingFactor>
    <mu1>0.2</mu1>
    <mu2>0.2</mu2>
    <kp>1e15</kp>
    <kd>1e13</kd>
    <selfCollide>true</selfCollide>
  </gazebo>
  <gazebo reference="phantom_link_0_1">
    <gravity>false</gravity>
    <dampingFactor>0.1</dampingFactor>
    <mu1>0.2</mu1>
    <mu2>0.2</mu2>
    <kp>1e15</kp>
    <kd>1e13</kd>
    <selfCollide>true</selfCollide>
  </gazebo>
  <gazebo reference="phantom_link_0_2">
    <gravity>false</gravity>
    <dampingFactor>0.1</dampingFactor>
    <mu1>0.2</mu1>
    <mu2>0.2</mu2>
    <kp>1e15</kp>
    <kd>1e13</kd>
    <selfCollide>true</selfCollide>
  </gazebo>
  <gazebo reference="phantom_link_0_3">
    <gravity>false</gravity>
    <dampingFactor>0.1</dampingFactor>
    <mu1>0.2</mu1>
    <mu2>0.2</mu2>
    <kp>1e15</kp>
    <kd>1e13</kd>
    <selfCollide>true</selfCollide>
  </gazebo>
  <gazebo reference="phantom_link_0_4">
    <gravity>false</gravity>
    <dampingFactor>0.1</dampingFactor>
    <mu1>0.2</mu1>
    <mu2>0.2</mu2>
    <kp>1e15</kp>
    <kd>1e13</kd>
    <selfCollide>true</selfCollide>
  </gazebo>
  <gazebo reference="phantom_link_0_5">
    <gravity>false</gravity>
    <dampingFactor>0.1</dampingFactor>
    <mu1>0.2</mu1>
    <mu2>0.2</mu2>
    <kp>1e15</kp>
    <kd>1e13</kd>
    <selfCollide>true</selfCollide>
  </gazebo>
  <gazebo reference="plate_0">
    <material>Gazebo/aluminum</material>
    <dampingFactor>0.1</dampingFactor>
    <mu1>0.2</mu1>
    <mu2>0.2</mu2>
    <kp>1e15</kp>
    <kd>1e13</kd>
  </gazebo>
  <gazebo reference="phantom_link_1_0">
    <gravity>false</gravity>
    <dampingFactor>0.1</dampingFactor>
    <mu1>0.2</mu1>
    <mu2>0.2</mu2>
    <kp>1e15</kp>
    <kd>1e13</kd>
    <selfCollide>true</selfCollide>
  </gazebo>
  <gazebo reference="phantom_link_1_1">
    <gravity>false</gravity>
    <dampingFactor>0.1</dampingFactor>
    <mu1>0.2</mu1>
    <mu2>0.2</mu2>
    <kp>1e15</kp>
    <kd>1e13</kd>
    <selfCollide>true</selfCollide>
  </gazebo>
  <gazebo reference="phantom_link_1_2">
    <gravity>false</gravity>
    <dampingFactor>0.1</dampingFactor>
    <mu1>0.2</mu1>
    <mu2>0.2</mu2>
    <kp>1e15</kp>
    <kd>1e13</kd>
    <selfCollide>true</selfCollide>
  </gazebo>
  <gazebo reference="phantom_link_1_3">
    <gravity>false</gravity>
    <dampingFactor>0.1</dampingFactor>
    <mu1>0.2</mu1>
    <mu2>0.2</mu2>
    <kp>1e15</kp>
    <kd>1e13</kd>
    <selfCollide>true</selfCollide>
  </gazebo>
  <gazebo reference="phantom_link_1_4">
    <gravity>false</gravity>
    <dampingFactor>0.1</dampingFactor>
    <mu1>0.2</mu1>
    <mu2>0.2</mu2>
    <kp>1e15</kp>
    <kd>1e13</kd>
    <selfCollide>true</selfCollide>
  </gazebo>
  <gazebo reference="phantom_link_1_5">
    <gravity>false</gravity>
    <dampingFactor>0.1</dampingFactor>
    <mu1>0.2</mu1>
    <mu2>0.2</mu2>
    <kp>1e15</kp>
    <kd>1e13</kd>
    <selfCollide>true</selfCollide>
  </gazebo>
  <gazebo reference="plate_1">
    <material>Gazebo/aluminum</material>
    <dampingFactor>0.1</dampingFactor>
    <mu1>0.2</mu1>
    <mu2>0.2</mu2>
    <kp>1e15</kp>
    <kd>1e13</kd>
  </gazebo>
  <gazebo reference="phantom_link_2_0">
    <gravity>false</gravity>
    <dampingFactor>0.1</dampingFactor>
    <mu1>0.2</mu1>
    <mu2>0.2</mu2>
    <kp>1e15</kp>
    <kd>1e13</kd>
    <selfCollide>true</selfCollide>
  </gazebo>
  <gazebo reference="phantom_link_2_1">
    <gravity>false</gravity>
    <dampingFactor>0.1</dampingFactor>
    <mu1>0.2</mu1>
    <mu2>0.2</mu2>
    <kp>1e15</kp>
    <kd>1e13</kd>
    <selfCollide>true</selfCollide>
  </gazebo>
  <gazebo reference="phantom_link_2_2">
    <gravity>false</gravity>
    <dampingFactor>0.1</dampingFactor>
    <mu1>0.2</mu1>
    <mu2>0.2</mu2>
    <kp>1e15</kp>
    <kd>1e13</kd>
    <selfCollide>true</selfCollide>
  </gazebo>
  <gazebo reference="phantom_link_2_3">
    <gravity>false</gravity>
    <dampingFactor>0.1</dampingFactor>
    <mu1>0.2</mu1>
    <mu2>0.2</mu2>
    <kp>1e15</kp>
    <kd>1e13</kd>
    <selfCollide>true</selfCollide>
  </gazebo>
  <gazebo reference="phantom_link_2_4">
    <gravity>false</gravity>
    <dampingFactor>0.1</dampingFactor>
    <mu1>0.2</mu1>
    <mu2>0.2</mu2>
    <kp>1e15</kp>
    <kd>1e13</kd>
    <selfCollide>true</selfCollide>
  </gazebo>
  <gazebo reference="phantom_link_2_5">
    <gravity>false</gravity>
    <dampingFactor>0.1</dampingFactor>
    <mu1>0.2</mu1>
    <mu2>0.2</mu2>
    <kp>1e15</kp>
    <kd>1e13</kd>
    <selfCollide>true</selfCollide>
  </gazebo>
  <gazebo reference="plate_2">
    <material>Gazebo/aluminum</material>
    <dampingFactor>0.1</dampingFactor>
    <mu1>0.2</mu1>
    <mu2>0.2</mu2>
    <kp>1e15</kp>
    <kd>1e13</kd>
  </gazebo>
  <gazebo reference="phantom_link_3_0">
    <gravity>false</gravity>
    <dampingFactor>0.1</dampingFactor>
    <mu1>0.2</mu1>
    <mu2>0.2</mu2>
    <kp>1e15</kp>
    <kd>1e13</kd>
    <selfCollide>true</selfCollide>
  </gazebo>
  <gazebo reference="phantom_link_3_1">
    <gravity>false</gravity>
    <dampingFactor>0.1</dampingFactor>
    <mu1>0.2</mu1>
    <mu2>0.2</mu2>
    <kp>1e15</kp>
    <kd>1e13</kd>
    <selfCollide>true</selfCollide>
  </gazebo>
  <gazebo reference="phantom_link_3_2">
    <gravity>false</gravity>
    <dampingFactor>0.1</dampingFactor>
    <mu1>0.2</mu1>
    <mu2>0.2</mu2>
    <kp>1e15</kp>
    <kd>1e13</kd>
    <selfCollide>true</selfCollide>
  </gazebo>
  <gazebo reference="phantom_link_3_3">
    <gravity>false</gravity>
    <dampingFactor>0.1</dampingFactor>
    <mu1>0.2</mu1>
    <mu2>0.2</mu2>
    <kp>1e15</kp>
    <kd>1e13</kd>
    <selfCollide>true</selfCollide>
  </gazebo>
  <gazebo reference="phantom_link_3_4">
    <gravity>false</gravity>
    <dampingFactor>0.1</dampingFactor>
    <mu1>0.2</mu1>
    <mu2>0.2</mu2>
    <kp>1e15</kp>
    <kd>1e13</kd>
    <selfCollide>true</selfCollide>
  </gazebo>
  <gazebo reference="phantom_link_3_5">
    <gravity>false</gravity>
    <dampingFactor>0.1</dampingFactor>
    <mu1>0.2</mu1>
    <mu2>0.2</mu2>
    <kp>1e15</kp>
    <kd>1e13</kd>
    <selfCollide>true</selfCollide>
  </gazebo>
  <gazebo reference="plate_3">
    <material>Gazebo/aluminum</material>
    <dampingFactor>0.1</dampingFactor>
    <mu1>0.2</mu1>
    <mu2>0.2</mu2>
    <kp>1e15</kp>
    <kd>1e13</kd>
  </gazebo>
  <gazebo reference="phantom_link_4_0">
    <gravity>false</gravity>
    <dampingFactor>0.1</dampingFactor>
    <mu1>0.2</mu1>
    <mu2>0.2</mu2>
    <kp>1e15</kp>
    <kd>1e13</kd>
    <selfCollide>true</selfCollide>
  </gazebo>
  <gazebo reference="phantom_link_4_1">
    <gravity>false</gravity>
    <dampingFactor>0.1</dampingFactor>
    <mu1>0.2</mu1>
    <mu2>0.2</mu2>
    <kp>1e15</kp>
    <kd>1e13</kd>
    <selfCollide>true</selfCollide>
  </gazebo>
  <gazebo reference="phantom_link_4_2">
    <gravity>false</gravity>
    <dampingFactor>0.1</dampingFactor>
    <mu1>0.2</mu1>
    <mu2>0.2</mu2>
    <kp>1e15</kp>
    <kd>1e13</kd>
    <selfCollide>true</selfCollide>
  </gazebo>
  <gazebo reference="phantom_link_4_3">
    <gravity>false</gravity>
    <dampingFactor>0.1</dampingFactor>
    <mu1>0.2</mu1>
    <mu2>0.2</mu2>
    <kp>1e15</kp>
    <kd>1e13</kd>
    <selfCollide>true</selfCollide>
  </gazebo>
  <gazebo reference="phantom_link_4_4">
    <gravity>false</gravity>
    <dampingFactor>0.1</dampingFactor>
    <mu1>0.2</mu1>
    <mu2>0.2</mu2>
    <kp>1e15</kp>
    <kd>1e13</kd>
    <selfCollide>true</selfCollide>
  </gazebo>
  <gazebo reference="phantom_link_4_5">
    <gravity>false</gravity>
    <dampingFactor>0.1</dampingFactor>
    <mu1>0.2</mu1>
    <mu2>0.2</mu2>
    <kp>1e15</kp>
    <kd>1e13</kd>
    <selfCollide>true</selfCollide>
  </gazebo>
  <gazebo reference="plate_4">
    <material>Gazebo/aluminum</material>
    <dampingFactor>0.1</dampingFactor>
    <mu1>0.2</mu1>
    <mu2>0.2</mu2>
    <kp>1e15</kp>
    <kd>1e13</kd>
  </gazebo>
  <gazebo reference="phantom_link_5_0">
    <gravity>false</gravity>
    <dampingFactor>0.1</dampingFactor>
    <mu1>0.2</mu1>
    <mu2>0.2</mu2>
    <kp>1e15</kp>
    <kd>1e13</kd>
    <selfCollide>true</selfCollide>
  </gazebo>
  <gazebo reference="phantom_link_5_1">
    <gravity>false</gravity>
    <dampingFactor>0.1</dampingFactor>
    <mu1>0.2</mu1>
    <mu2>0.2</mu2>
    <kp>1e15</kp>
    <kd>1e13</kd>
    <selfCollide>true</selfCollide>
  </gazebo>
  <gazebo reference="phantom_link_5_2">
    <gravity>false</gravity>
    <dampingFactor>0.1</dampingFactor>
    <mu1>0.2</mu1>
    <mu2>0.2</mu2>
    <kp>1e15</kp>
    <kd>1e13</kd>
    <selfCollide>true</selfCollide>
  </gazebo>
  <gazebo reference="phantom_link_5_3">
    <gravity>false</gravity>
    <dampingFactor>0.1</dampingFactor>
    <mu1>0.2</mu1>
    <mu2>0.2</mu2>
    <kp>1e15</kp>
    <kd>1e13</kd>
    <selfCollide>true</selfCollide>
  </gazebo>
  <gazebo reference="phantom_link_5_4">
    <gravity>false</gravity>
    <dampingFactor>0.1</dampingFactor>
    <mu1>0.2</mu1>
    <mu2>0.2</mu2>
    <kp>1e15</kp>
    <kd>1e13</kd>
    <selfCollide>true</selfCollide>
  </gazebo>
  <gazebo reference="phantom_link_5_5">
    <gravity>false</gravity>
    <dampingFactor>0.1</dampingFactor>
    <mu1>0.2</mu1>
    <mu2>0.2</mu2>
    <kp>1e15</kp>
    <kd>1e13</kd>
    <selfCollide>true</selfCollide>
  </gazebo>
  <gazebo reference="plate_5">
    <material>Gazebo/aluminum</material>
    <dampingFactor>0.1</dampingFactor>
    <mu1>0.2</mu1>
    <mu2>0.2</mu2>
    <kp>1e15</kp>
    <kd>1e13</kd>
  </gazebo>
  <gazebo reference="phantom_joint_segment_0_1_beta">
    </gazebo>
  <gazebo reference="phantom_joint_segment_0_2_alpha2">
    <springStiffness>20</springStiffness>
    <springReference>0</springReference>
  </gazebo>
  <gazebo reference="phantom_joint_segment_0_3_translation">
    <springStiffness>15000</springStiffness>
    <springReference>0</springReference>
  </gazebo>
  <gazebo reference="phantom_joint_segment_0_4_alpha2">
    <springStiffness>20</springStiffness>
    <springReference>0</springReference>
  </gazebo>
  <gazebo reference="phantom_joint_segment_0_5_betaN">
    </gazebo>
  <gazebo reference="phantom_joint_segment_1_1_beta">
    </gazebo>
  <gazebo reference="phantom_joint_segment_1_2_alpha2">
    <springStiffness>20</springStiffness>
    <springReference>0</springReference>
  </gazebo>
  <gazebo reference="phantom_joint_segment_1_3_translation">
    <springStiffness>15000</springStiffness>
    <springReference>0</springReference>
  </gazebo>
  <gazebo reference="phantom_joint_segment_1_4_alpha2">
    <springStiffness>20</springStiffness>
    <springReference>0</springReference>
  </gazebo>
  <gazebo reference="phantom_joint_segment_1_5_betaN">
    </gazebo>
  <gazebo reference="phantom_joint_segment_2_1_beta">
    </gazebo>
  <gazebo reference="phantom_joint_segment_2_2_alpha2">
    <springStiffness>20</springStiffness>
    <springReference>0</springReference>
  </gazebo>
  <gazebo reference="phantom_joint_segment_2_3_translation">
    <springStiffness>15000</springStiffness>
    <springReference>0</springReference>
  </gazebo>
  <gazebo reference="phantom_joint_segment_2_4_alpha2">
    <springStiffness>20</springStiffness>
    <springReference>0</springReference>
  </gazebo>
  <gazebo reference="phantom_joint_segment_2_5_betaN">
    </gazebo>
  <gazebo reference="phantom_joint_segment_3_1_beta">
    </gazebo>
  <gazebo reference="phantom_joint_segment_3_2_alpha2">
    <springStiffness>20</springStiffness>
    <springReference>0</springReference>
  </gazebo>
  <gazebo reference="phantom_joint_segment_3_3_translation">
    <springStiffness>15000</springStiffness>
    <springReference>0</springReference>
  </gazebo>
  <gazebo reference="phantom_joint_segment_3_4_alpha2">
    <springStiffness>20</springStiffness>
    <springReference>0</springReference>
  </gazebo>
  <gazebo reference="phantom_joint_segment_3_5_betaN">
    </gazebo>
  <gazebo reference="phantom_joint_segment_4_1_beta">
    </gazebo>
  <gazebo reference="phantom_joint_segment_4_2_alpha2">
    <springStiffness>20</springStiffness>
    <springReference>0</springReference>
  </gazebo>
  <gazebo reference="phantom_joint_segment_4_3_translation">
    <springStiffness>15000</springStiffness>
    <springReference>0</springReference>
  </gazebo>
  <gazebo reference="phantom_joint_segment_4_4_alpha2">
    <springStiffness>20</springStiffness>
    <springReference>0</springReference>
  </gazebo>
  <gazebo reference="phantom_joint_segment_4_5_betaN">
    </gazebo>
  <gazebo reference="phantom_joint_segment_5_1_beta">
    </gazebo>
  <gazebo reference="phantom_joint_segment_5_2_alpha2">
    <springStiffness>20</springStiffness>
    <springReference>0</springReference>
  </gazebo>
  <gazebo reference="phantom_joint_segment_5_3_translation">
    <springStiffness>15000</springStiffness>
    <springReference>0</springReference>
  </gazebo>
  <gazebo reference="phantom_joint_segment_5_4_alpha2">
    <springStiffness>20</springStiffness>
    <springReference>0</springReference>
  </gazebo>
  <gazebo reference="phantom_joint_segment_5_5_betaN">
    </gazebo>
</robot>
