<sdf version='1.7'>
  <model name='origarmRigidKE'>
    <joint name='fixed' type='fixed'>
      <pose relative_to='__model__'>0 0 1 3.14159 -0 0</pose>
      <parent>world</parent>
      <child>plate_-1</child>
    </joint>
    <link name='plate_-1'>
      <pose relative_to='fixed'>0 0 0 0 -0 0</pose>
      <inertial>
        <pose>0 0 0 0 -0 0</pose>
        <mass>0.127</mass>
        <inertia>
          <ixx>0.00032197</ixx>
          <ixy>0</ixy>
          <ixz>0</ixz>
          <iyy>0.00032197</iyy>
          <iyz>0</iyz>
          <izz>0.00064284</izz>
        </inertia>
      </inertial>
      <collision name='plate_-1_collision'>
        <pose>0 0 0 0 -0 0</pose>
        <geometry>
          <cylinder>
            <length>0.005</length>
            <radius>0.095</radius>
          </cylinder>
        </geometry>
      </collision>
      <visual name='plate_-1_visual'>
        <pose>0 0 0 0 -0 0</pose>
        <geometry>
          <mesh>
            <scale>1 1 1</scale>
            <uri>model://origarm_ros/model/mesh/origarmPlate_m.STL</uri>
          </mesh>
        </geometry>
      </visual>
    </link>
    <joint name='phantom_joint_segment_0_1_beta' type='revolute'>
      <pose relative_to='plate_-1'>0 0 0 0 -0 0</pose>
      <parent>plate_-1</parent>
      <child>phantom_link_0_1</child>
      <axis>
        <xyz>0 0 1</xyz>
        <limit>
          <lower>-6.28319</lower>
          <upper>6.28319</upper>
          <effort>200</effort>
          <velocity>20</velocity>
        </limit>
        <dynamics>
          <damping>0.7</damping>
          <friction>0.3</friction>
          <spring_reference>0</spring_reference>
          <spring_stiffness>0</spring_stiffness>
        </dynamics>
      </axis>
      <physics>
        <ode>
          <limit>
            <cfm>0</cfm>
            <erp>0.2</erp>
          </limit>
        </ode>
      </physics>
    </joint>
    <link name='phantom_link_0_1'>
      <pose relative_to='phantom_joint_segment_0_1_beta'>0 0 0 0 -0 0</pose>
      <inertial>
        <pose>0 0 0 0 -0 0</pose>
        <mass>0.01</mass>
        <inertia>
          <ixx>0.001</ixx>
          <ixy>0</ixy>
          <ixz>0</ixz>
          <iyy>0.001</iyy>
          <iyz>0</iyz>
          <izz>0.001</izz>
        </inertia>
      </inertial>
      <visual name='phantom_link_0_1_visual'>
        <pose>0 0 0 0 -0 0</pose>
        <geometry>
          <cylinder>
            <length>0.002</length>
            <radius>0.005</radius>
          </cylinder>
        </geometry>
      </visual>
      <gravity>1</gravity>
      <velocity_decay>
        <linear>0.1</linear>
        <angular>0.1</angular>
      </velocity_decay>
      <self_collide>1</self_collide>
      <gravity>0</gravity>
    </link>
    <joint name='phantom_joint_segment_0_2_alpha2' type='revolute'>
      <pose relative_to='phantom_link_0_1'>0 0 0 0 -0 0</pose>
      <parent>phantom_link_0_1</parent>
      <child>phantom_link_0_2</child>
      <axis>
        <xyz>0 1 0</xyz>
        <limit>
          <lower>0</lower>
          <upper>0.25</upper>
          <effort>200</effort>
          <velocity>20</velocity>
        </limit>
        <dynamics>
          <damping>0.7</damping>
          <friction>0.3</friction>
          <spring_reference>0</spring_reference>
          <spring_stiffness>20</spring_stiffness>
        </dynamics>
      </axis>
      <physics>
        <ode>
          <limit>
            <cfm>0</cfm>
            <erp>0.2</erp>
          </limit>
        </ode>
      </physics>
    </joint>
    <link name='phantom_link_0_2'>
      <pose relative_to='phantom_joint_segment_0_2_alpha2'>0 0 0 0 -0 0</pose>
      <inertial>
        <pose>0 0 0 0 -0 0</pose>
        <mass>0.01</mass>
        <inertia>
          <ixx>0.001</ixx>
          <ixy>0</ixy>
          <ixz>0</ixz>
          <iyy>0.001</iyy>
          <iyz>0</iyz>
          <izz>0.001</izz>
        </inertia>
      </inertial>
      <visual name='phantom_link_0_2_visual'>
        <pose>0 0 0 0 -0 0</pose>
        <geometry>
          <cylinder>
            <length>0.002</length>
            <radius>0.005</radius>
          </cylinder>
        </geometry>
      </visual>
      <gravity>1</gravity>
      <velocity_decay>
        <linear>0.1</linear>
        <angular>0.1</angular>
      </velocity_decay>
      <self_collide>1</self_collide>
      <gravity>0</gravity>
    </link>
    <joint name='phantom_joint_segment_0_3_translation' type='prismatic'>
      <pose relative_to='phantom_link_0_2'>0 0 0.055 0 -0 0</pose>
      <parent>phantom_link_0_2</parent>
      <child>phantom_link_0_3</child>
      <axis>
        <xyz>0 0 1</xyz>
        <limit>
          <lower>-0.02</lower>
          <upper>0.03</upper>
          <effort>200</effort>
          <velocity>20</velocity>
        </limit>
        <dynamics>
          <damping>0.7</damping>
          <friction>0.5</friction>
          <spring_reference>0</spring_reference>
          <spring_stiffness>15000</spring_stiffness>
        </dynamics>
      </axis>
      <physics>
        <ode>
          <limit>
            <cfm>0</cfm>
            <erp>0.2</erp>
          </limit>
        </ode>
      </physics>
    </joint>
    <link name='phantom_link_0_3'>
      <pose relative_to='phantom_joint_segment_0_3_translation'>0 0 0 0 -0 0</pose>
      <inertial>
        <pose>0 0 0 0 -0 0</pose>
        <mass>0.01</mass>
        <inertia>
          <ixx>0.001</ixx>
          <ixy>0</ixy>
          <ixz>0</ixz>
          <iyy>0.001</iyy>
          <iyz>0</iyz>
          <izz>0.001</izz>
        </inertia>
      </inertial>
      <visual name='phantom_link_0_3_visual'>
        <pose>0 0 0 0 -0 0</pose>
        <geometry>
          <cylinder>
            <length>0.002</length>
            <radius>0.005</radius>
          </cylinder>
        </geometry>
      </visual>
      <gravity>1</gravity>
      <velocity_decay>
        <linear>0.1</linear>
        <angular>0.1</angular>
      </velocity_decay>
      <self_collide>1</self_collide>
      <gravity>0</gravity>
    </link>
    <joint name='phantom_joint_segment_0_4_alpha2' type='revolute'>
      <pose relative_to='phantom_link_0_3'>0 0 0 0 -0 0</pose>
      <parent>phantom_link_0_3</parent>
      <child>phantom_link_0_4</child>
      <axis>
        <xyz>0 1 0</xyz>
        <limit>
          <lower>0</lower>
          <upper>0.25</upper>
          <effort>200</effort>
          <velocity>20</velocity>
        </limit>
        <dynamics>
          <damping>0.7</damping>
          <friction>0.3</friction>
          <spring_reference>0</spring_reference>
          <spring_stiffness>20</spring_stiffness>
        </dynamics>
      </axis>
      <physics>
        <ode>
          <limit>
            <cfm>0</cfm>
            <erp>0.2</erp>
          </limit>
        </ode>
      </physics>
    </joint>
    <link name='phantom_link_0_4'>
      <pose relative_to='phantom_joint_segment_0_4_alpha2'>0 0 0 0 -0 0</pose>
      <inertial>
        <pose>0 0 0 0 -0 0</pose>
        <mass>0.01</mass>
        <inertia>
          <ixx>0.001</ixx>
          <ixy>0</ixy>
          <ixz>0</ixz>
          <iyy>0.001</iyy>
          <iyz>0</iyz>
          <izz>0.001</izz>
        </inertia>
      </inertial>
      <visual name='phantom_link_0_4_visual'>
        <pose>0 0 0 0 -0 0</pose>
        <geometry>
          <cylinder>
            <length>0.002</length>
            <radius>0.005</radius>
          </cylinder>
        </geometry>
      </visual>
      <gravity>1</gravity>
      <velocity_decay>
        <linear>0.1</linear>
        <angular>0.1</angular>
      </velocity_decay>
      <self_collide>1</self_collide>
      <gravity>0</gravity>
    </link>
    <joint name='phantom_joint_segment_0_5_betaN' type='revolute'>
      <pose relative_to='phantom_link_0_4'>0 0 0 0 -0 0</pose>
      <parent>phantom_link_0_4</parent>
      <child>plate_0</child>
      <axis>
        <xyz>0 0 1</xyz>
        <limit>
          <lower>-6.28319</lower>
          <upper>6.28319</upper>
          <effort>200</effort>
          <velocity>20</velocity>
        </limit>
        <dynamics>
          <damping>0.7</damping>
          <friction>0.3</friction>
          <spring_reference>0</spring_reference>
          <spring_stiffness>0</spring_stiffness>
        </dynamics>
      </axis>
      <physics>
        <ode>
          <limit>
            <cfm>0</cfm>
            <erp>0.2</erp>
          </limit>
        </ode>
      </physics>
    </joint>
    <link name='plate_0'>
      <pose relative_to='phantom_joint_segment_0_5_betaN'>0 0 0 0 -0 0</pose>
      <inertial>
        <pose>0 0 0 0 -0 0</pose>
        <mass>0.127</mass>
        <inertia>
          <ixx>0.00032197</ixx>
          <ixy>0</ixy>
          <ixz>0</ixz>
          <iyy>0.00032197</iyy>
          <iyz>0</iyz>
          <izz>0.00064284</izz>
        </inertia>
      </inertial>
      <collision name='plate_0_collision'>
        <pose>0 0 0 0 -0 0</pose>
        <geometry>
          <cylinder>
            <length>0.005</length>
            <radius>0.095</radius>
          </cylinder>
        </geometry>
        <surface>
          <contact>
            <ode>
              <kp>1e+15</kp>
              <kd>1e+13</kd>
            </ode>
          </contact>
          <friction>
            <ode>
              <mu>0.2</mu>
              <mu2>0.2</mu2>
            </ode>
          </friction>
        </surface>
      </collision>
      <visual name='plate_0_visual'>
        <pose>0 0 0 0 -0 0</pose>
        <geometry>
          <mesh>
            <scale>1 1 1</scale>
            <uri>model://origarm_ros/model/mesh/origarmPlate_m.STL</uri>
          </mesh>
        </geometry>
        <material>
          <script>
            <name>Gazebo/aluminum</name>
            <uri>file://media/materials/scripts/gazebo.material</uri>
          </script>
        </material>
      </visual>
      <gravity>1</gravity>
      <velocity_decay>
        <linear>0.1</linear>
        <angular>0.1</angular>
      </velocity_decay>
    </link>
    <joint name='phantom_joint_segment_1_1_beta' type='revolute'>
      <pose relative_to='plate_0'>0 0 0 0 -0 0</pose>
      <parent>plate_0</parent>
      <child>phantom_link_1_1</child>
      <axis>
        <xyz>0 0 1</xyz>
        <limit>
          <lower>-6.28319</lower>
          <upper>6.28319</upper>
          <effort>200</effort>
          <velocity>20</velocity>
        </limit>
        <dynamics>
          <damping>0.7</damping>
          <friction>0.3</friction>
          <spring_reference>0</spring_reference>
          <spring_stiffness>0</spring_stiffness>
        </dynamics>
      </axis>
      <physics>
        <ode>
          <limit>
            <cfm>0</cfm>
            <erp>0.2</erp>
          </limit>
        </ode>
      </physics>
    </joint>
    <link name='phantom_link_1_1'>
      <pose relative_to='phantom_joint_segment_1_1_beta'>0 0 0 0 -0 0</pose>
      <inertial>
        <pose>0 0 0 0 -0 0</pose>
        <mass>0.01</mass>
        <inertia>
          <ixx>0.001</ixx>
          <ixy>0</ixy>
          <ixz>0</ixz>
          <iyy>0.001</iyy>
          <iyz>0</iyz>
          <izz>0.001</izz>
        </inertia>
      </inertial>
      <visual name='phantom_link_1_1_visual'>
        <pose>0 0 0 0 -0 0</pose>
        <geometry>
          <cylinder>
            <length>0.002</length>
            <radius>0.005</radius>
          </cylinder>
        </geometry>
      </visual>
      <gravity>1</gravity>
      <velocity_decay>
        <linear>0.1</linear>
        <angular>0.1</angular>
      </velocity_decay>
      <self_collide>1</self_collide>
      <gravity>0</gravity>
    </link>
    <joint name='phantom_joint_segment_1_2_alpha2' type='revolute'>
      <pose relative_to='phantom_link_1_1'>0 0 0 0 -0 0</pose>
      <parent>phantom_link_1_1</parent>
      <child>phantom_link_1_2</child>
      <axis>
        <xyz>0 1 0</xyz>
        <limit>
          <lower>0</lower>
          <upper>0.25</upper>
          <effort>200</effort>
          <velocity>20</velocity>
        </limit>
        <dynamics>
          <damping>0.7</damping>
          <friction>0.3</friction>
          <spring_reference>0</spring_reference>
          <spring_stiffness>20</spring_stiffness>
        </dynamics>
      </axis>
      <physics>
        <ode>
          <limit>
            <cfm>0</cfm>
            <erp>0.2</erp>
          </limit>
        </ode>
      </physics>
    </joint>
    <link name='phantom_link_1_2'>
      <pose relative_to='phantom_joint_segment_1_2_alpha2'>0 0 0 0 -0 0</pose>
      <inertial>
        <pose>0 0 0 0 -0 0</pose>
        <mass>0.01</mass>
        <inertia>
          <ixx>0.001</ixx>
          <ixy>0</ixy>
          <ixz>0</ixz>
          <iyy>0.001</iyy>
          <iyz>0</iyz>
          <izz>0.001</izz>
        </inertia>
      </inertial>
      <visual name='phantom_link_1_2_visual'>
        <pose>0 0 0 0 -0 0</pose>
        <geometry>
          <cylinder>
            <length>0.002</length>
            <radius>0.005</radius>
          </cylinder>
        </geometry>
      </visual>
      <gravity>1</gravity>
      <velocity_decay>
        <linear>0.1</linear>
        <angular>0.1</angular>
      </velocity_decay>
      <self_collide>1</self_collide>
      <gravity>0</gravity>
    </link>
    <joint name='phantom_joint_segment_1_3_translation' type='prismatic'>
      <pose relative_to='phantom_link_1_2'>0 0 0.055 0 -0 0</pose>
      <parent>phantom_link_1_2</parent>
      <child>phantom_link_1_3</child>
      <axis>
        <xyz>0 0 1</xyz>
        <limit>
          <lower>-0.02</lower>
          <upper>0.03</upper>
          <effort>200</effort>
          <velocity>20</velocity>
        </limit>
        <dynamics>
          <damping>0.7</damping>
          <friction>0.5</friction>
          <spring_reference>0</spring_reference>
          <spring_stiffness>15000</spring_stiffness>
        </dynamics>
      </axis>
      <physics>
        <ode>
          <limit>
            <cfm>0</cfm>
            <erp>0.2</erp>
          </limit>
        </ode>
      </physics>
    </joint>
    <link name='phantom_link_1_3'>
      <pose relative_to='phantom_joint_segment_1_3_translation'>0 0 0 0 -0 0</pose>
      <inertial>
        <pose>0 0 0 0 -0 0</pose>
        <mass>0.01</mass>
        <inertia>
          <ixx>0.001</ixx>
          <ixy>0</ixy>
          <ixz>0</ixz>
          <iyy>0.001</iyy>
          <iyz>0</iyz>
          <izz>0.001</izz>
        </inertia>
      </inertial>
      <visual name='phantom_link_1_3_visual'>
        <pose>0 0 0 0 -0 0</pose>
        <geometry>
          <cylinder>
            <length>0.002</length>
            <radius>0.005</radius>
          </cylinder>
        </geometry>
      </visual>
      <gravity>1</gravity>
      <velocity_decay>
        <linear>0.1</linear>
        <angular>0.1</angular>
      </velocity_decay>
      <self_collide>1</self_collide>
      <gravity>0</gravity>
    </link>
    <joint name='phantom_joint_segment_1_4_alpha2' type='revolute'>
      <pose relative_to='phantom_link_1_3'>0 0 0 0 -0 0</pose>
      <parent>phantom_link_1_3</parent>
      <child>phantom_link_1_4</child>
      <axis>
        <xyz>0 1 0</xyz>
        <limit>
          <lower>0</lower>
          <upper>0.25</upper>
          <effort>200</effort>
          <velocity>20</velocity>
        </limit>
        <dynamics>
          <damping>0.7</damping>
          <friction>0.3</friction>
          <spring_reference>0</spring_reference>
          <spring_stiffness>20</spring_stiffness>
        </dynamics>
      </axis>
      <physics>
        <ode>
          <limit>
            <cfm>0</cfm>
            <erp>0.2</erp>
          </limit>
        </ode>
      </physics>
    </joint>
    <link name='phantom_link_1_4'>
      <pose relative_to='phantom_joint_segment_1_4_alpha2'>0 0 0 0 -0 0</pose>
      <inertial>
        <pose>0 0 0 0 -0 0</pose>
        <mass>0.01</mass>
        <inertia>
          <ixx>0.001</ixx>
          <ixy>0</ixy>
          <ixz>0</ixz>
          <iyy>0.001</iyy>
          <iyz>0</iyz>
          <izz>0.001</izz>
        </inertia>
      </inertial>
      <visual name='phantom_link_1_4_visual'>
        <pose>0 0 0 0 -0 0</pose>
        <geometry>
          <cylinder>
            <length>0.002</length>
            <radius>0.005</radius>
          </cylinder>
        </geometry>
      </visual>
      <gravity>1</gravity>
      <velocity_decay>
        <linear>0.1</linear>
        <angular>0.1</angular>
      </velocity_decay>
      <self_collide>1</self_collide>
      <gravity>0</gravity>
    </link>
    <joint name='phantom_joint_segment_1_5_betaN' type='revolute'>
      <pose relative_to='phantom_link_1_4'>0 0 0 0 -0 0</pose>
      <parent>phantom_link_1_4</parent>
      <child>plate_1</child>
      <axis>
        <xyz>0 0 1</xyz>
        <limit>
          <lower>-6.28319</lower>
          <upper>6.28319</upper>
          <effort>200</effort>
          <velocity>20</velocity>
        </limit>
        <dynamics>
          <damping>0.7</damping>
          <friction>0.3</friction>
          <spring_reference>0</spring_reference>
          <spring_stiffness>0</spring_stiffness>
        </dynamics>
      </axis>
      <physics>
        <ode>
          <limit>
            <cfm>0</cfm>
            <erp>0.2</erp>
          </limit>
        </ode>
      </physics>
    </joint>
    <link name='plate_1'>
      <pose relative_to='phantom_joint_segment_1_5_betaN'>0 0 0 0 -0 0</pose>
      <inertial>
        <pose>0 0 0 0 -0 0</pose>
        <mass>0.127</mass>
        <inertia>
          <ixx>0.00032197</ixx>
          <ixy>0</ixy>
          <ixz>0</ixz>
          <iyy>0.00032197</iyy>
          <iyz>0</iyz>
          <izz>0.00064284</izz>
        </inertia>
      </inertial>
      <collision name='plate_1_collision'>
        <pose>0 0 0 0 -0 0</pose>
        <geometry>
          <cylinder>
            <length>0.005</length>
            <radius>0.095</radius>
          </cylinder>
        </geometry>
        <surface>
          <contact>
            <ode>
              <kp>1e+15</kp>
              <kd>1e+13</kd>
            </ode>
          </contact>
          <friction>
            <ode>
              <mu>0.2</mu>
              <mu2>0.2</mu2>
            </ode>
          </friction>
        </surface>
      </collision>
      <visual name='plate_1_visual'>
        <pose>0 0 0 0 -0 0</pose>
        <geometry>
          <mesh>
            <scale>1 1 1</scale>
            <uri>model://origarm_ros/model/mesh/origarmPlate_m.STL</uri>
          </mesh>
        </geometry>
        <material>
          <script>
            <name>Gazebo/aluminum</name>
            <uri>file://media/materials/scripts/gazebo.material</uri>
          </script>
        </material>
      </visual>
      <gravity>1</gravity>
      <velocity_decay>
        <linear>0.1</linear>
        <angular>0.1</angular>
      </velocity_decay>
    </link>
    <joint name='phantom_joint_segment_2_1_beta' type='revolute'>
      <pose relative_to='plate_1'>0 0 0 0 -0 0</pose>
      <parent>plate_1</parent>
      <child>phantom_link_2_1</child>
      <axis>
        <xyz>0 0 1</xyz>
        <limit>
          <lower>-6.28319</lower>
          <upper>6.28319</upper>
          <effort>200</effort>
          <velocity>20</velocity>
        </limit>
        <dynamics>
          <damping>0.7</damping>
          <friction>0.3</friction>
          <spring_reference>0</spring_reference>
          <spring_stiffness>0</spring_stiffness>
        </dynamics>
      </axis>
      <physics>
        <ode>
          <limit>
            <cfm>0</cfm>
            <erp>0.2</erp>
          </limit>
        </ode>
      </physics>
    </joint>
    <link name='phantom_link_2_1'>
      <pose relative_to='phantom_joint_segment_2_1_beta'>0 0 0 0 -0 0</pose>
      <inertial>
        <pose>0 0 0 0 -0 0</pose>
        <mass>0.01</mass>
        <inertia>
          <ixx>0.001</ixx>
          <ixy>0</ixy>
          <ixz>0</ixz>
          <iyy>0.001</iyy>
          <iyz>0</iyz>
          <izz>0.001</izz>
        </inertia>
      </inertial>
      <visual name='phantom_link_2_1_visual'>
        <pose>0 0 0 0 -0 0</pose>
        <geometry>
          <cylinder>
            <length>0.002</length>
            <radius>0.005</radius>
          </cylinder>
        </geometry>
      </visual>
      <gravity>1</gravity>
      <velocity_decay>
        <linear>0.1</linear>
        <angular>0.1</angular>
      </velocity_decay>
      <self_collide>1</self_collide>
      <gravity>0</gravity>
    </link>
    <joint name='phantom_joint_segment_2_2_alpha2' type='revolute'>
      <pose relative_to='phantom_link_2_1'>0 0 0 0 -0 0</pose>
      <parent>phantom_link_2_1</parent>
      <child>phantom_link_2_2</child>
      <axis>
        <xyz>0 1 0</xyz>
        <limit>
          <lower>0</lower>
          <upper>0.25</upper>
          <effort>200</effort>
          <velocity>20</velocity>
        </limit>
        <dynamics>
          <damping>0.7</damping>
          <friction>0.3</friction>
          <spring_reference>0</spring_reference>
          <spring_stiffness>20</spring_stiffness>
        </dynamics>
      </axis>
      <physics>
        <ode>
          <limit>
            <cfm>0</cfm>
            <erp>0.2</erp>
          </limit>
        </ode>
      </physics>
    </joint>
    <link name='phantom_link_2_2'>
      <pose relative_to='phantom_joint_segment_2_2_alpha2'>0 0 0 0 -0 0</pose>
      <inertial>
        <pose>0 0 0 0 -0 0</pose>
        <mass>0.01</mass>
        <inertia>
          <ixx>0.001</ixx>
          <ixy>0</ixy>
          <ixz>0</ixz>
          <iyy>0.001</iyy>
          <iyz>0</iyz>
          <izz>0.001</izz>
        </inertia>
      </inertial>
      <visual name='phantom_link_2_2_visual'>
        <pose>0 0 0 0 -0 0</pose>
        <geometry>
          <cylinder>
            <length>0.002</length>
            <radius>0.005</radius>
          </cylinder>
        </geometry>
      </visual>
      <gravity>1</gravity>
      <velocity_decay>
        <linear>0.1</linear>
        <angular>0.1</angular>
      </velocity_decay>
      <self_collide>1</self_collide>
      <gravity>0</gravity>
    </link>
    <joint name='phantom_joint_segment_2_3_translation' type='prismatic'>
      <pose relative_to='phantom_link_2_2'>0 0 0.055 0 -0 0</pose>
      <parent>phantom_link_2_2</parent>
      <child>phantom_link_2_3</child>
      <axis>
        <xyz>0 0 1</xyz>
        <limit>
          <lower>-0.02</lower>
          <upper>0.03</upper>
          <effort>200</effort>
          <velocity>20</velocity>
        </limit>
        <dynamics>
          <damping>0.7</damping>
          <friction>0.5</friction>
          <spring_reference>0</spring_reference>
          <spring_stiffness>15000</spring_stiffness>
        </dynamics>
      </axis>
      <physics>
        <ode>
          <limit>
            <cfm>0</cfm>
            <erp>0.2</erp>
          </limit>
        </ode>
      </physics>
    </joint>
    <link name='phantom_link_2_3'>
      <pose relative_to='phantom_joint_segment_2_3_translation'>0 0 0 0 -0 0</pose>
      <inertial>
        <pose>0 0 0 0 -0 0</pose>
        <mass>0.01</mass>
        <inertia>
          <ixx>0.001</ixx>
          <ixy>0</ixy>
          <ixz>0</ixz>
          <iyy>0.001</iyy>
          <iyz>0</iyz>
          <izz>0.001</izz>
        </inertia>
      </inertial>
      <visual name='phantom_link_2_3_visual'>
        <pose>0 0 0 0 -0 0</pose>
        <geometry>
          <cylinder>
            <length>0.002</length>
            <radius>0.005</radius>
          </cylinder>
        </geometry>
      </visual>
      <gravity>1</gravity>
      <velocity_decay>
        <linear>0.1</linear>
        <angular>0.1</angular>
      </velocity_decay>
      <self_collide>1</self_collide>
      <gravity>0</gravity>
    </link>
    <joint name='phantom_joint_segment_2_4_alpha2' type='revolute'>
      <pose relative_to='phantom_link_2_3'>0 0 0 0 -0 0</pose>
      <parent>phantom_link_2_3</parent>
      <child>phantom_link_2_4</child>
      <axis>
        <xyz>0 1 0</xyz>
        <limit>
          <lower>0</lower>
          <upper>0.25</upper>
          <effort>200</effort>
          <velocity>20</velocity>
        </limit>
        <dynamics>
          <damping>0.7</damping>
          <friction>0.3</friction>
          <spring_reference>0</spring_reference>
          <spring_stiffness>20</spring_stiffness>
        </dynamics>
      </axis>
      <physics>
        <ode>
          <limit>
            <cfm>0</cfm>
            <erp>0.2</erp>
          </limit>
        </ode>
      </physics>
    </joint>
    <link name='phantom_link_2_4'>
      <pose relative_to='phantom_joint_segment_2_4_alpha2'>0 0 0 0 -0 0</pose>
      <inertial>
        <pose>0 0 0 0 -0 0</pose>
        <mass>0.01</mass>
        <inertia>
          <ixx>0.001</ixx>
          <ixy>0</ixy>
          <ixz>0</ixz>
          <iyy>0.001</iyy>
          <iyz>0</iyz>
          <izz>0.001</izz>
        </inertia>
      </inertial>
      <visual name='phantom_link_2_4_visual'>
        <pose>0 0 0 0 -0 0</pose>
        <geometry>
          <cylinder>
            <length>0.002</length>
            <radius>0.005</radius>
          </cylinder>
        </geometry>
      </visual>
      <gravity>1</gravity>
      <velocity_decay>
        <linear>0.1</linear>
        <angular>0.1</angular>
      </velocity_decay>
      <self_collide>1</self_collide>
      <gravity>0</gravity>
    </link>
    <joint name='phantom_joint_segment_2_5_betaN' type='revolute'>
      <pose relative_to='phantom_link_2_4'>0 0 0 0 -0 0</pose>
      <parent>phantom_link_2_4</parent>
      <child>plate_2</child>
      <axis>
        <xyz>0 0 1</xyz>
        <limit>
          <lower>-6.28319</lower>
          <upper>6.28319</upper>
          <effort>200</effort>
          <velocity>20</velocity>
        </limit>
        <dynamics>
          <damping>0.7</damping>
          <friction>0.3</friction>
          <spring_reference>0</spring_reference>
          <spring_stiffness>0</spring_stiffness>
        </dynamics>
      </axis>
      <physics>
        <ode>
          <limit>
            <cfm>0</cfm>
            <erp>0.2</erp>
          </limit>
        </ode>
      </physics>
    </joint>
    <link name='plate_2'>
      <pose relative_to='phantom_joint_segment_2_5_betaN'>0 0 0 0 -0 0</pose>
      <inertial>
        <pose>0 0 0 0 -0 0</pose>
        <mass>0.127</mass>
        <inertia>
          <ixx>0.00032197</ixx>
          <ixy>0</ixy>
          <ixz>0</ixz>
          <iyy>0.00032197</iyy>
          <iyz>0</iyz>
          <izz>0.00064284</izz>
        </inertia>
      </inertial>
      <collision name='plate_2_collision'>
        <pose>0 0 0 0 -0 0</pose>
        <geometry>
          <cylinder>
            <length>0.005</length>
            <radius>0.095</radius>
          </cylinder>
        </geometry>
        <surface>
          <contact>
            <ode>
              <kp>1e+15</kp>
              <kd>1e+13</kd>
            </ode>
          </contact>
          <friction>
            <ode>
              <mu>0.2</mu>
              <mu2>0.2</mu2>
            </ode>
          </friction>
        </surface>
      </collision>
      <visual name='plate_2_visual'>
        <pose>0 0 0 0 -0 0</pose>
        <geometry>
          <mesh>
            <scale>1 1 1</scale>
            <uri>model://origarm_ros/model/mesh/origarmPlate_m.STL</uri>
          </mesh>
        </geometry>
        <material>
          <script>
            <name>Gazebo/aluminum</name>
            <uri>file://media/materials/scripts/gazebo.material</uri>
          </script>
        </material>
      </visual>
      <gravity>1</gravity>
      <velocity_decay>
        <linear>0.1</linear>
        <angular>0.1</angular>
      </velocity_decay>
    </link>
    <joint name='phantom_joint_segment_3_1_beta' type='revolute'>
      <pose relative_to='plate_2'>0 0 0 0 -0 0</pose>
      <parent>plate_2</parent>
      <child>phantom_link_3_1</child>
      <axis>
        <xyz>0 0 1</xyz>
        <limit>
          <lower>-6.28319</lower>
          <upper>6.28319</upper>
          <effort>200</effort>
          <velocity>20</velocity>
        </limit>
        <dynamics>
          <damping>0.7</damping>
          <friction>0.3</friction>
          <spring_reference>0</spring_reference>
          <spring_stiffness>0</spring_stiffness>
        </dynamics>
      </axis>
      <physics>
        <ode>
          <limit>
            <cfm>0</cfm>
            <erp>0.2</erp>
          </limit>
        </ode>
      </physics>
    </joint>
    <link name='phantom_link_3_1'>
      <pose relative_to='phantom_joint_segment_3_1_beta'>0 0 0 0 -0 0</pose>
      <inertial>
        <pose>0 0 0 0 -0 0</pose>
        <mass>0.01</mass>
        <inertia>
          <ixx>0.001</ixx>
          <ixy>0</ixy>
          <ixz>0</ixz>
          <iyy>0.001</iyy>
          <iyz>0</iyz>
          <izz>0.001</izz>
        </inertia>
      </inertial>
      <visual name='phantom_link_3_1_visual'>
        <pose>0 0 0 0 -0 0</pose>
        <geometry>
          <cylinder>
            <length>0.002</length>
            <radius>0.005</radius>
          </cylinder>
        </geometry>
      </visual>
      <gravity>1</gravity>
      <velocity_decay>
        <linear>0.1</linear>
        <angular>0.1</angular>
      </velocity_decay>
      <self_collide>1</self_collide>
      <gravity>0</gravity>
    </link>
    <joint name='phantom_joint_segment_3_2_alpha2' type='revolute'>
      <pose relative_to='phantom_link_3_1'>0 0 0 0 -0 0</pose>
      <parent>phantom_link_3_1</parent>
      <child>phantom_link_3_2</child>
      <axis>
        <xyz>0 1 0</xyz>
        <limit>
          <lower>0</lower>
          <upper>0.25</upper>
          <effort>200</effort>
          <velocity>20</velocity>
        </limit>
        <dynamics>
          <damping>0.7</damping>
          <friction>0.3</friction>
          <spring_reference>0</spring_reference>
          <spring_stiffness>20</spring_stiffness>
        </dynamics>
      </axis>
      <physics>
        <ode>
          <limit>
            <cfm>0</cfm>
            <erp>0.2</erp>
          </limit>
        </ode>
      </physics>
    </joint>
    <link name='phantom_link_3_2'>
      <pose relative_to='phantom_joint_segment_3_2_alpha2'>0 0 0 0 -0 0</pose>
      <inertial>
        <pose>0 0 0 0 -0 0</pose>
        <mass>0.01</mass>
        <inertia>
          <ixx>0.001</ixx>
          <ixy>0</ixy>
          <ixz>0</ixz>
          <iyy>0.001</iyy>
          <iyz>0</iyz>
          <izz>0.001</izz>
        </inertia>
      </inertial>
      <visual name='phantom_link_3_2_visual'>
        <pose>0 0 0 0 -0 0</pose>
        <geometry>
          <cylinder>
            <length>0.002</length>
            <radius>0.005</radius>
          </cylinder>
        </geometry>
      </visual>
      <gravity>1</gravity>
      <velocity_decay>
        <linear>0.1</linear>
        <angular>0.1</angular>
      </velocity_decay>
      <self_collide>1</self_collide>
      <gravity>0</gravity>
    </link>
    <joint name='phantom_joint_segment_3_3_translation' type='prismatic'>
      <pose relative_to='phantom_link_3_2'>0 0 0.055 0 -0 0</pose>
      <parent>phantom_link_3_2</parent>
      <child>phantom_link_3_3</child>
      <axis>
        <xyz>0 0 1</xyz>
        <limit>
          <lower>-0.02</lower>
          <upper>0.03</upper>
          <effort>200</effort>
          <velocity>20</velocity>
        </limit>
        <dynamics>
          <damping>0.7</damping>
          <friction>0.5</friction>
          <spring_reference>0</spring_reference>
          <spring_stiffness>15000</spring_stiffness>
        </dynamics>
      </axis>
      <physics>
        <ode>
          <limit>
            <cfm>0</cfm>
            <erp>0.2</erp>
          </limit>
        </ode>
      </physics>
    </joint>
    <link name='phantom_link_3_3'>
      <pose relative_to='phantom_joint_segment_3_3_translation'>0 0 0 0 -0 0</pose>
      <inertial>
        <pose>0 0 0 0 -0 0</pose>
        <mass>0.01</mass>
        <inertia>
          <ixx>0.001</ixx>
          <ixy>0</ixy>
          <ixz>0</ixz>
          <iyy>0.001</iyy>
          <iyz>0</iyz>
          <izz>0.001</izz>
        </inertia>
      </inertial>
      <visual name='phantom_link_3_3_visual'>
        <pose>0 0 0 0 -0 0</pose>
        <geometry>
          <cylinder>
            <length>0.002</length>
            <radius>0.005</radius>
          </cylinder>
        </geometry>
      </visual>
      <gravity>1</gravity>
      <velocity_decay>
        <linear>0.1</linear>
        <angular>0.1</angular>
      </velocity_decay>
      <self_collide>1</self_collide>
      <gravity>0</gravity>
    </link>
    <joint name='phantom_joint_segment_3_4_alpha2' type='revolute'>
      <pose relative_to='phantom_link_3_3'>0 0 0 0 -0 0</pose>
      <parent>phantom_link_3_3</parent>
      <child>phantom_link_3_4</child>
      <axis>
        <xyz>0 1 0</xyz>
        <limit>
          <lower>0</lower>
          <upper>0.25</upper>
          <effort>200</effort>
          <velocity>20</velocity>
        </limit>
        <dynamics>
          <damping>0.7</damping>
          <friction>0.3</friction>
          <spring_reference>0</spring_reference>
          <spring_stiffness>20</spring_stiffness>
        </dynamics>
      </axis>
      <physics>
        <ode>
          <limit>
            <cfm>0</cfm>
            <erp>0.2</erp>
          </limit>
        </ode>
      </physics>
    </joint>
    <link name='phantom_link_3_4'>
      <pose relative_to='phantom_joint_segment_3_4_alpha2'>0 0 0 0 -0 0</pose>
      <inertial>
        <pose>0 0 0 0 -0 0</pose>
        <mass>0.01</mass>
        <inertia>
          <ixx>0.001</ixx>
          <ixy>0</ixy>
          <ixz>0</ixz>
          <iyy>0.001</iyy>
          <iyz>0</iyz>
          <izz>0.001</izz>
        </inertia>
      </inertial>
      <visual name='phantom_link_3_4_visual'>
        <pose>0 0 0 0 -0 0</pose>
        <geometry>
          <cylinder>
            <length>0.002</length>
            <radius>0.005</radius>
          </cylinder>
        </geometry>
      </visual>
      <gravity>1</gravity>
      <velocity_decay>
        <linear>0.1</linear>
        <angular>0.1</angular>
      </velocity_decay>
      <self_collide>1</self_collide>
      <gravity>0</gravity>
    </link>
    <joint name='phantom_joint_segment_3_5_betaN' type='revolute'>
      <pose relative_to='phantom_link_3_4'>0 0 0 0 -0 0</pose>
      <parent>phantom_link_3_4</parent>
      <child>plate_3</child>
      <axis>
        <xyz>0 0 1</xyz>
        <limit>
          <lower>-6.28319</lower>
          <upper>6.28319</upper>
          <effort>200</effort>
          <velocity>20</velocity>
        </limit>
        <dynamics>
          <damping>0.7</damping>
          <friction>0.3</friction>
          <spring_reference>0</spring_reference>
          <spring_stiffness>0</spring_stiffness>
        </dynamics>
      </axis>
      <physics>
        <ode>
          <limit>
            <cfm>0</cfm>
            <erp>0.2</erp>
          </limit>
        </ode>
      </physics>
    </joint>
    <link name='plate_3'>
      <pose relative_to='phantom_joint_segment_3_5_betaN'>0 0 0 0 -0 0</pose>
      <inertial>
        <pose>0 0 0 0 -0 0</pose>
        <mass>0.127</mass>
        <inertia>
          <ixx>0.00032197</ixx>
          <ixy>0</ixy>
          <ixz>0</ixz>
          <iyy>0.00032197</iyy>
          <iyz>0</iyz>
          <izz>0.00064284</izz>
        </inertia>
      </inertial>
      <collision name='plate_3_collision'>
        <pose>0 0 0 0 -0 0</pose>
        <geometry>
          <cylinder>
            <length>0.005</length>
            <radius>0.095</radius>
          </cylinder>
        </geometry>
        <surface>
          <contact>
            <ode>
              <kp>1e+15</kp>
              <kd>1e+13</kd>
            </ode>
          </contact>
          <friction>
            <ode>
              <mu>0.2</mu>
              <mu2>0.2</mu2>
            </ode>
          </friction>
        </surface>
      </collision>
      <visual name='plate_3_visual'>
        <pose>0 0 0 0 -0 0</pose>
        <geometry>
          <mesh>
            <scale>1 1 1</scale>
            <uri>model://origarm_ros/model/mesh/origarmPlate_m.STL</uri>
          </mesh>
        </geometry>
        <material>
          <script>
            <name>Gazebo/aluminum</name>
            <uri>file://media/materials/scripts/gazebo.material</uri>
          </script>
        </material>
      </visual>
      <gravity>1</gravity>
      <velocity_decay>
        <linear>0.1</linear>
        <angular>0.1</angular>
      </velocity_decay>
    </link>
    <joint name='phantom_joint_segment_4_1_beta' type='revolute'>
      <pose relative_to='plate_3'>0 0 0 0 -0 0</pose>
      <parent>plate_3</parent>
      <child>phantom_link_4_1</child>
      <axis>
        <xyz>0 0 1</xyz>
        <limit>
          <lower>-6.28319</lower>
          <upper>6.28319</upper>
          <effort>200</effort>
          <velocity>20</velocity>
        </limit>
        <dynamics>
          <damping>0.7</damping>
          <friction>0.3</friction>
          <spring_reference>0</spring_reference>
          <spring_stiffness>0</spring_stiffness>
        </dynamics>
      </axis>
      <physics>
        <ode>
          <limit>
            <cfm>0</cfm>
            <erp>0.2</erp>
          </limit>
        </ode>
      </physics>
    </joint>
    <link name='phantom_link_4_1'>
      <pose relative_to='phantom_joint_segment_4_1_beta'>0 0 0 0 -0 0</pose>
      <inertial>
        <pose>0 0 0 0 -0 0</pose>
        <mass>0.01</mass>
        <inertia>
          <ixx>0.001</ixx>
          <ixy>0</ixy>
          <ixz>0</ixz>
          <iyy>0.001</iyy>
          <iyz>0</iyz>
          <izz>0.001</izz>
        </inertia>
      </inertial>
      <visual name='phantom_link_4_1_visual'>
        <pose>0 0 0 0 -0 0</pose>
        <geometry>
          <cylinder>
            <length>0.002</length>
            <radius>0.005</radius>
          </cylinder>
        </geometry>
      </visual>
      <gravity>1</gravity>
      <velocity_decay>
        <linear>0.1</linear>
        <angular>0.1</angular>
      </velocity_decay>
      <self_collide>1</self_collide>
      <gravity>0</gravity>
    </link>
    <joint name='phantom_joint_segment_4_2_alpha2' type='revolute'>
      <pose relative_to='phantom_link_4_1'>0 0 0 0 -0 0</pose>
      <parent>phantom_link_4_1</parent>
      <child>phantom_link_4_2</child>
      <axis>
        <xyz>0 1 0</xyz>
        <limit>
          <lower>0</lower>
          <upper>0.25</upper>
          <effort>200</effort>
          <velocity>20</velocity>
        </limit>
        <dynamics>
          <damping>0.7</damping>
          <friction>0.3</friction>
          <spring_reference>0</spring_reference>
          <spring_stiffness>20</spring_stiffness>
        </dynamics>
      </axis>
      <physics>
        <ode>
          <limit>
            <cfm>0</cfm>
            <erp>0.2</erp>
          </limit>
        </ode>
      </physics>
    </joint>
    <link name='phantom_link_4_2'>
      <pose relative_to='phantom_joint_segment_4_2_alpha2'>0 0 0 0 -0 0</pose>
      <inertial>
        <pose>0 0 0 0 -0 0</pose>
        <mass>0.01</mass>
        <inertia>
          <ixx>0.001</ixx>
          <ixy>0</ixy>
          <ixz>0</ixz>
          <iyy>0.001</iyy>
          <iyz>0</iyz>
          <izz>0.001</izz>
        </inertia>
      </inertial>
      <visual name='phantom_link_4_2_visual'>
        <pose>0 0 0 0 -0 0</pose>
        <geometry>
          <cylinder>
            <length>0.002</length>
            <radius>0.005</radius>
          </cylinder>
        </geometry>
      </visual>
      <gravity>1</gravity>
      <velocity_decay>
        <linear>0.1</linear>
        <angular>0.1</angular>
      </velocity_decay>
      <self_collide>1</self_collide>
      <gravity>0</gravity>
    </link>
    <joint name='phantom_joint_segment_4_3_translation' type='prismatic'>
      <pose relative_to='phantom_link_4_2'>0 0 0.055 0 -0 0</pose>
      <parent>phantom_link_4_2</parent>
      <child>phantom_link_4_3</child>
      <axis>
        <xyz>0 0 1</xyz>
        <limit>
          <lower>-0.02</lower>
          <upper>0.03</upper>
          <effort>200</effort>
          <velocity>20</velocity>
        </limit>
        <dynamics>
          <damping>0.7</damping>
          <friction>0.5</friction>
          <spring_reference>0</spring_reference>
          <spring_stiffness>15000</spring_stiffness>
        </dynamics>
      </axis>
      <physics>
        <ode>
          <limit>
            <cfm>0</cfm>
            <erp>0.2</erp>
          </limit>
        </ode>
      </physics>
    </joint>
    <link name='phantom_link_4_3'>
      <pose relative_to='phantom_joint_segment_4_3_translation'>0 0 0 0 -0 0</pose>
      <inertial>
        <pose>0 0 0 0 -0 0</pose>
        <mass>0.01</mass>
        <inertia>
          <ixx>0.001</ixx>
          <ixy>0</ixy>
          <ixz>0</ixz>
          <iyy>0.001</iyy>
          <iyz>0</iyz>
          <izz>0.001</izz>
        </inertia>
      </inertial>
      <visual name='phantom_link_4_3_visual'>
        <pose>0 0 0 0 -0 0</pose>
        <geometry>
          <cylinder>
            <length>0.002</length>
            <radius>0.005</radius>
          </cylinder>
        </geometry>
      </visual>
      <gravity>1</gravity>
      <velocity_decay>
        <linear>0.1</linear>
        <angular>0.1</angular>
      </velocity_decay>
      <self_collide>1</self_collide>
      <gravity>0</gravity>
    </link>
    <joint name='phantom_joint_segment_4_4_alpha2' type='revolute'>
      <pose relative_to='phantom_link_4_3'>0 0 0 0 -0 0</pose>
      <parent>phantom_link_4_3</parent>
      <child>phantom_link_4_4</child>
      <axis>
        <xyz>0 1 0</xyz>
        <limit>
          <lower>0</lower>
          <upper>0.25</upper>
          <effort>200</effort>
          <velocity>20</velocity>
        </limit>
        <dynamics>
          <damping>0.7</damping>
          <friction>0.3</friction>
          <spring_reference>0</spring_reference>
          <spring_stiffness>20</spring_stiffness>
        </dynamics>
      </axis>
      <physics>
        <ode>
          <limit>
            <cfm>0</cfm>
            <erp>0.2</erp>
          </limit>
        </ode>
      </physics>
    </joint>
    <link name='phantom_link_4_4'>
      <pose relative_to='phantom_joint_segment_4_4_alpha2'>0 0 0 0 -0 0</pose>
      <inertial>
        <pose>0 0 0 0 -0 0</pose>
        <mass>0.01</mass>
        <inertia>
          <ixx>0.001</ixx>
          <ixy>0</ixy>
          <ixz>0</ixz>
          <iyy>0.001</iyy>
          <iyz>0</iyz>
          <izz>0.001</izz>
        </inertia>
      </inertial>
      <visual name='phantom_link_4_4_visual'>
        <pose>0 0 0 0 -0 0</pose>
        <geometry>
          <cylinder>
            <length>0.002</length>
            <radius>0.005</radius>
          </cylinder>
        </geometry>
      </visual>
      <gravity>1</gravity>
      <velocity_decay>
        <linear>0.1</linear>
        <angular>0.1</angular>
      </velocity_decay>
      <self_collide>1</self_collide>
      <gravity>0</gravity>
    </link>
    <joint name='phantom_joint_segment_4_5_betaN' type='revolute'>
      <pose relative_to='phantom_link_4_4'>0 0 0 0 -0 0</pose>
      <parent>phantom_link_4_4</parent>
      <child>plate_4</child>
      <axis>
        <xyz>0 0 1</xyz>
        <limit>
          <lower>-6.28319</lower>
          <upper>6.28319</upper>
          <effort>200</effort>
          <velocity>20</velocity>
        </limit>
        <dynamics>
          <damping>0.7</damping>
          <friction>0.3</friction>
          <spring_reference>0</spring_reference>
          <spring_stiffness>0</spring_stiffness>
        </dynamics>
      </axis>
      <physics>
        <ode>
          <limit>
            <cfm>0</cfm>
            <erp>0.2</erp>
          </limit>
        </ode>
      </physics>
    </joint>
    <link name='plate_4'>
      <pose relative_to='phantom_joint_segment_4_5_betaN'>0 0 0 0 -0 0</pose>
      <inertial>
        <pose>0 0 0 0 -0 0</pose>
        <mass>0.127</mass>
        <inertia>
          <ixx>0.00032197</ixx>
          <ixy>0</ixy>
          <ixz>0</ixz>
          <iyy>0.00032197</iyy>
          <iyz>0</iyz>
          <izz>0.00064284</izz>
        </inertia>
      </inertial>
      <collision name='plate_4_collision'>
        <pose>0 0 0 0 -0 0</pose>
        <geometry>
          <cylinder>
            <length>0.005</length>
            <radius>0.095</radius>
          </cylinder>
        </geometry>
        <surface>
          <contact>
            <ode>
              <kp>1e+15</kp>
              <kd>1e+13</kd>
            </ode>
          </contact>
          <friction>
            <ode>
              <mu>0.2</mu>
              <mu2>0.2</mu2>
            </ode>
          </friction>
        </surface>
      </collision>
      <visual name='plate_4_visual'>
        <pose>0 0 0 0 -0 0</pose>
        <geometry>
          <mesh>
            <scale>1 1 1</scale>
            <uri>model://origarm_ros/model/mesh/origarmPlate_m.STL</uri>
          </mesh>
        </geometry>
        <material>
          <script>
            <name>Gazebo/aluminum</name>
            <uri>file://media/materials/scripts/gazebo.material</uri>
          </script>
        </material>
      </visual>
      <gravity>1</gravity>
      <velocity_decay>
        <linear>0.1</linear>
        <angular>0.1</angular>
      </velocity_decay>
    </link>
    <joint name='phantom_joint_segment_5_1_beta' type='revolute'>
      <pose relative_to='plate_4'>0 0 0 0 -0 0</pose>
      <parent>plate_4</parent>
      <child>phantom_link_5_1</child>
      <axis>
        <xyz>0 0 1</xyz>
        <limit>
          <lower>-6.28319</lower>
          <upper>6.28319</upper>
          <effort>200</effort>
          <velocity>20</velocity>
        </limit>
        <dynamics>
          <damping>0.7</damping>
          <friction>0.3</friction>
          <spring_reference>0</spring_reference>
          <spring_stiffness>0</spring_stiffness>
        </dynamics>
      </axis>
      <physics>
        <ode>
          <limit>
            <cfm>0</cfm>
            <erp>0.2</erp>
          </limit>
        </ode>
      </physics>
    </joint>
    <link name='phantom_link_5_1'>
      <pose relative_to='phantom_joint_segment_5_1_beta'>0 0 0 0 -0 0</pose>
      <inertial>
        <pose>0 0 0 0 -0 0</pose>
        <mass>0.01</mass>
        <inertia>
          <ixx>0.001</ixx>
          <ixy>0</ixy>
          <ixz>0</ixz>
          <iyy>0.001</iyy>
          <iyz>0</iyz>
          <izz>0.001</izz>
        </inertia>
      </inertial>
      <visual name='phantom_link_5_1_visual'>
        <pose>0 0 0 0 -0 0</pose>
        <geometry>
          <cylinder>
            <length>0.002</length>
            <radius>0.005</radius>
          </cylinder>
        </geometry>
      </visual>
      <gravity>1</gravity>
      <velocity_decay>
        <linear>0.1</linear>
        <angular>0.1</angular>
      </velocity_decay>
      <self_collide>1</self_collide>
      <gravity>0</gravity>
    </link>
    <joint name='phantom_joint_segment_5_2_alpha2' type='revolute'>
      <pose relative_to='phantom_link_5_1'>0 0 0 0 -0 0</pose>
      <parent>phantom_link_5_1</parent>
      <child>phantom_link_5_2</child>
      <axis>
        <xyz>0 1 0</xyz>
        <limit>
          <lower>0</lower>
          <upper>0.25</upper>
          <effort>200</effort>
          <velocity>20</velocity>
        </limit>
        <dynamics>
          <damping>0.7</damping>
          <friction>0.3</friction>
          <spring_reference>0</spring_reference>
          <spring_stiffness>20</spring_stiffness>
        </dynamics>
      </axis>
      <physics>
        <ode>
          <limit>
            <cfm>0</cfm>
            <erp>0.2</erp>
          </limit>
        </ode>
      </physics>
    </joint>
    <link name='phantom_link_5_2'>
      <pose relative_to='phantom_joint_segment_5_2_alpha2'>0 0 0 0 -0 0</pose>
      <inertial>
        <pose>0 0 0 0 -0 0</pose>
        <mass>0.01</mass>
        <inertia>
          <ixx>0.001</ixx>
          <ixy>0</ixy>
          <ixz>0</ixz>
          <iyy>0.001</iyy>
          <iyz>0</iyz>
          <izz>0.001</izz>
        </inertia>
      </inertial>
      <visual name='phantom_link_5_2_visual'>
        <pose>0 0 0 0 -0 0</pose>
        <geometry>
          <cylinder>
            <length>0.002</length>
            <radius>0.005</radius>
          </cylinder>
        </geometry>
      </visual>
      <gravity>1</gravity>
      <velocity_decay>
        <linear>0.1</linear>
        <angular>0.1</angular>
      </velocity_decay>
      <self_collide>1</self_collide>
      <gravity>0</gravity>
    </link>
    <joint name='phantom_joint_segment_5_3_translation' type='prismatic'>
      <pose relative_to='phantom_link_5_2'>0 0 0.055 0 -0 0</pose>
      <parent>phantom_link_5_2</parent>
      <child>phantom_link_5_3</child>
      <axis>
        <xyz>0 0 1</xyz>
        <limit>
          <lower>-0.02</lower>
          <upper>0.03</upper>
          <effort>200</effort>
          <velocity>20</velocity>
        </limit>
        <dynamics>
          <damping>0.7</damping>
          <friction>0.5</friction>
          <spring_reference>0</spring_reference>
          <spring_stiffness>15000</spring_stiffness>
        </dynamics>
      </axis>
      <physics>
        <ode>
          <limit>
            <cfm>0</cfm>
            <erp>0.2</erp>
          </limit>
        </ode>
      </physics>
    </joint>
    <link name='phantom_link_5_3'>
      <pose relative_to='phantom_joint_segment_5_3_translation'>0 0 0 0 -0 0</pose>
      <inertial>
        <pose>0 0 0 0 -0 0</pose>
        <mass>0.01</mass>
        <inertia>
          <ixx>0.001</ixx>
          <ixy>0</ixy>
          <ixz>0</ixz>
          <iyy>0.001</iyy>
          <iyz>0</iyz>
          <izz>0.001</izz>
        </inertia>
      </inertial>
      <visual name='phantom_link_5_3_visual'>
        <pose>0 0 0 0 -0 0</pose>
        <geometry>
          <cylinder>
            <length>0.002</length>
            <radius>0.005</radius>
          </cylinder>
        </geometry>
      </visual>
      <gravity>1</gravity>
      <velocity_decay>
        <linear>0.1</linear>
        <angular>0.1</angular>
      </velocity_decay>
      <self_collide>1</self_collide>
      <gravity>0</gravity>
    </link>
    <joint name='phantom_joint_segment_5_4_alpha2' type='revolute'>
      <pose relative_to='phantom_link_5_3'>0 0 0 0 -0 0</pose>
      <parent>phantom_link_5_3</parent>
      <child>phantom_link_5_4</child>
      <axis>
        <xyz>0 1 0</xyz>
        <limit>
          <lower>0</lower>
          <upper>0.25</upper>
          <effort>200</effort>
          <velocity>20</velocity>
        </limit>
        <dynamics>
          <damping>0.7</damping>
          <friction>0.3</friction>
          <spring_reference>0</spring_reference>
          <spring_stiffness>20</spring_stiffness>
        </dynamics>
      </axis>
      <physics>
        <ode>
          <limit>
            <cfm>0</cfm>
            <erp>0.2</erp>
          </limit>
        </ode>
      </physics>
    </joint>
    <link name='phantom_link_5_4'>
      <pose relative_to='phantom_joint_segment_5_4_alpha2'>0 0 0 0 -0 0</pose>
      <inertial>
        <pose>0 0 0 0 -0 0</pose>
        <mass>0.01</mass>
        <inertia>
          <ixx>0.001</ixx>
          <ixy>0</ixy>
          <ixz>0</ixz>
          <iyy>0.001</iyy>
          <iyz>0</iyz>
          <izz>0.001</izz>
        </inertia>
      </inertial>
      <visual name='phantom_link_5_4_visual'>
        <pose>0 0 0 0 -0 0</pose>
        <geometry>
          <cylinder>
            <length>0.002</length>
            <radius>0.005</radius>
          </cylinder>
        </geometry>
      </visual>
      <gravity>1</gravity>
      <velocity_decay>
        <linear>0.1</linear>
        <angular>0.1</angular>
      </velocity_decay>
      <self_collide>1</self_collide>
      <gravity>0</gravity>
    </link>
    <joint name='phantom_joint_segment_5_5_betaN' type='revolute'>
      <pose relative_to='phantom_link_5_4'>0 0 0 0 -0 0</pose>
      <parent>phantom_link_5_4</parent>
      <child>plate_5</child>
      <axis>
        <xyz>0 0 1</xyz>
        <limit>
          <lower>-6.28319</lower>
          <upper>6.28319</upper>
          <effort>200</effort>
          <velocity>20</velocity>
        </limit>
        <dynamics>
          <damping>0.7</damping>
          <friction>0.3</friction>
          <spring_reference>0</spring_reference>
          <spring_stiffness>0</spring_stiffness>
        </dynamics>
      </axis>
      <physics>
        <ode>
          <limit>
            <cfm>0</cfm>
            <erp>0.2</erp>
          </limit>
        </ode>
      </physics>
    </joint>
    <link name='plate_5'>
      <pose relative_to='phantom_joint_segment_5_5_betaN'>0 0 0 0 -0 0</pose>
      <inertial>
        <pose>0 0 0 0 -0 0</pose>
        <mass>0.127</mass>
        <inertia>
          <ixx>0.00032197</ixx>
          <ixy>0</ixy>
          <ixz>0</ixz>
          <iyy>0.00032197</iyy>
          <iyz>0</iyz>
          <izz>0.00064284</izz>
        </inertia>
      </inertial>
      <collision name='plate_5_collision'>
        <pose>0 0 0 0 -0 0</pose>
        <geometry>
          <cylinder>
            <length>0.005</length>
            <radius>0.095</radius>
          </cylinder>
        </geometry>
        <surface>
          <contact>
            <ode>
              <kp>1e+15</kp>
              <kd>1e+13</kd>
            </ode>
          </contact>
          <friction>
            <ode>
              <mu>0.2</mu>
              <mu2>0.2</mu2>
            </ode>
          </friction>
        </surface>
      </collision>
      <visual name='plate_5_visual'>
        <pose>0 0 0 0 -0 0</pose>
        <geometry>
          <mesh>
            <scale>1 1 1</scale>
            <uri>model://origarm_ros/model/mesh/origarmPlate_m.STL</uri>
          </mesh>
        </geometry>
        <material>
          <script>
            <name>Gazebo/aluminum</name>
            <uri>file://media/materials/scripts/gazebo.material</uri>
          </script>
        </material>
      </visual>
      <gravity>1</gravity>
      <velocity_decay>
        <linear>0.1</linear>
        <angular>0.1</angular>
      </velocity_decay>
    </link>
    <static>0</static>
    <plugin name='gazebo_ros_control' filename='libgazebo_ros_control.so'>
      <robotNamespace>/origarmRigidKE</robotNamespace>
    </plugin>
  </model>
</sdf>
